Workbook
Name 二级科目: TB!$B$3:$B$20
Name 科目表: [1]TB!$A$3:[1]TB!$A$170
Name 科目表: TB!$A$3:$A$170
Name 科目设置: TB!$A$3:$A$170
Name 三级科目: TB!$C$3:$C$3

Sheet 目录
B2: 货币资金审计工作底稿
B3: 工作表名 | C3: 工作底稿名称 | D3: 是否需要编制 | E3: 索引号 | G3: 所属会计师事务所： 广东中职信会计师事务所（特殊普通合伙）
B4: 1010 | C4: 货币资金实质性程序 | D4: 是 | E4: 1010 | G4: 被审计单位： | H4: 广州钢力金属制品总厂有限公司 | I4: 被审计单位简称： | J4: 钢力金属 | K4: 货币单位： | L4: 人民币/元
B5: 1010-1 | C5: 货币资金科目审计调整分录 | D5: 是 | E5: 1010-1 | G5: 会计期间： | H5: 2024-1-1至2024-12-31 | I5: 编制人： | J5: 黄振通 | K5: 日期： | L5: 2025-1-23
B6: 1010-2 | C6: 货币资金审定表 | D6: 是 | E6: 1010-2 | G6: 截止日期： | H6: 2024-12-31 | I6: 复核人： | J6: 王裕昆 | K6: 日期： | L6: 2025-2-10
B7: 1010-3-1 | C7: 库存现金明细表 | D7: 是 | E7: 1010-3-1
B8: 1010-3-2 | C8: 银行存款明细表 | D8: 是 | E8: 1010-3-2
B9: 1010-3-3 | C9: 其他货币资金明细表 | D9: 是 | E9: 1010-3-3
B10: 1010-4 | C10: 保险柜检查记录表 | D10: 是 | E10: 1010-4
B11: 1010-5 | C11: 已开立银行账户清单与账面银行账户双向核对 | D11: 是 | E11: 1010-5
B12: 1010-6 | C12: 银行账户网银核查情况表 | D12: 是 | E12: 1010-6
B13: 1010-7 | C13: 货币资金截止性测试表 | D13: 是 | E13: 1010-7
B14: 1010-8 | C14: 银行余额调节以及未达账项汇总表 | D14: 是 | E14: 1010-8
B15: 1010-9 | C15: 银行存单检查表 | D15: 是 | E15: 1010-9
B16: 1010-10 | C16: 货币资金受限情况明细表 | D16: 是 | E16: 1010-10
B17: 1010-11 | C17: 货币资金外币折算表 | D17: 是 | E17: 1010-11
B18: 1010-12 | C18: 银行存款账面收付记录与银行对账单抽样核对表 | D18: 是 | E18: 1010-12
... B20: 1010-14 | C20: 大额现金交易合理性检查程序表 | D20: 是 | E20: 1010-14
B21: 1011 | C21: 货币资金函证程序 | D21: 是 | E21: 1011
G25: =C22&D22

Sheet 1010
A1: << | B1: 货币资金实质性程序 | J1: 索引号： | K1: =目录!E4 -> 1010
B2: =目录!G4&目录!J4&" "&目录!G5&目录!H5&" "&目录!G6&目录!H6&" "&目录!I5&目录!J5&目录!L5&" "&目录!I6&目录!J6&目录!L6 -> 被审计单位：钢力金属 会计期间：2024-1-1至2024-12-31 截止日期：2024-12-31 编制人：黄振通2025-1-23 复核人：王裕昆2025-2-10
B4: 审计目标 | G4: 财务报表认定
G5: 存在 | H5: 完整性 | I5: 权利和义务 | J5: 计价和分摊 | K5: 分类和列报
B6: A | D6: 资产负债表中记录的货币资金是存在的。 | G6: √
B7: B | D7: 所有应当记录的货币资金均已记录。 | H7: √ | L7: =K7 -> 0
B8: C | D8: 记录的货币资金由被审计单位拥有或控制。 | I8: √ | L8: =K9 -> 0
B9: D | D9: 货币资金以恰当的金额包括在财务报表中，与之相关的计价调整已恰当记录。 | J9: √
B10: E | D10: 货币资金已按照企业会计准则的规定在财务报表中作出恰当列报。 | K10: √
B11: 计划实施的实质性程序
B12: 审计目标 | C12: 序号 | D12: 实质性程序 | E12: 是否执行 | F12: 索引号 | G12: 存在 | H12: 完整性 | I12: 权利和义务 | J12: 计价和分摊 | K12: 分类和列报
D13: （一）库存现金
B14: D | C14: 1 | D14: 核对库存现金日记账与总账的金额是否相符，检查非记账本位币库存现金的折算汇率及折算金额是否正确。 | E14: 是 | F14: =目录!E7&"、"&目录!E17 -> 1010-3-1、1010-11 | J14: √
B16: ABCD | C16: 2 | D16: 监盘库存现金： （1）制定监盘计划，确定监盘时间； （2）将盘点金额与现金日记账余额进行核对，如有差异，应要求被审计单位查明原因并作适当调整，如无法查明原因，应要求被审计单位按管理权限批准后作出调整； （3）在非资产负债表日进行盘点时，应调整至资产负债表日的金额； （4）若有充抵库存现金的借条、未提现支票、未作报销的原始凭证,需在盘点表中注明，如有必要应作调整,特别关注数家公司混用现金保险箱的情况。 | E16: 是 | F16: =目录!E10 -> 1010-4 | G16: √ | H16: √ | I16: √ | J16: √
B17: ADB | C17: 3 | D17: 抽查大额库存现金收支。检查原始凭证是否齐全、记账凭证与原始凭证是否相符、账务处理是否正确、是否记录于恰当的会计期间等项内容。 | E17: 是 | F17: =目录!E19 -> 1010-13 | G17: √ | H17: √ | J17: √
C18: 4 | D18: 根据评估的舞弊风险等因素增加的其他审计程序。
C19: 5 | D19: 如果被审计单位的现金交易比例较高，注册会计师需要了解和评估现金交易比例较高的合理性，是否与其业务性质相匹配，是否采取了适当措施保证现金收支完整、准确、安全。除实施其他审计程序外，注册会计师还应实施以下审计程序： | E19: 是 | F19: =目录!E20 -> 1010-14
D20: （1）了解和评价被审计单位与现金交易相关的内部控制，针对现金收支相关控制运行的有效性，获取充分、适当的审计证据。如果被审计单位使用收银设备管理现金收款业务，且相关收银系统与被审计单位财务系统相关联，注册会计师需要考虑针对信息系统一般控制和应用控制执行审计工作。 | G20: √ | H20: √ | J20: √ | K20: √
D21: （2）结合对生产、采购、销售、工薪等业务循环相关报表项目的审计结果，分析评价现金交易的合理性，关注现金使用范围是否符合相关规定。 | G21: √ | H21: √ | J21: √ | K21: √
D22: （3）计算月现金销售收款、现金采购付款的占比，识别现金收、付款比例是否存在异常波动，并追查异常波动原因。 | G22: √ | H22: √ | J22: √ | K22: √
D23: （4）了解现金交易对方的情况。向主要的现金交易对方函证被审计期间内发生的交易金额。在必要时，注册会计师可以选取现金结算量较大的交易对方进行实地观察或询问，关注交易对方经营业务的性质、规模与收付款项的性质、规模是否一致，关注使用现金结算的合理性。如果交易对方为个人，必要时，可以考虑与其联系以核实交易的真实性。 | G23: √ | H23: √ | J23: √ | K23: √
D24: （5）检查大额现金收支，追踪来源和去向，核对至交易的原始单据，关注收付款方、收付款金额与合同、订单、出入库单相关信息是否一致。 | G24: √ | H24: √ | J24: √ | K24: √
D25: （6）注重外部证据的检查。例如，对于农业行业，针对农产品管理特点，可以获取质检报告、检验检疫合格证、采伐资质、由税务局代开发票的资料副本等外部信息，验证其交易真实性。 | G25: √ | H25: √ | J25: √ | K25: √
D26: （7）对现金采购、销售交易过程实施观察程序。 | G26: √ | H26: √ | J26: √ | K26: √
D27: （8）对库存现金实施突击监盘程序，对被审计单位库存现金存放在两处或两处以上的，可以考虑同时实施监盘；在账面库存现金为零的情况下，仍然检查保险柜，查看是否有白条、员工的工资卡及其他异常文件。 | G27: √ | H27: √ | J27: √ | K27: √
D28: （9）关注各币种外币汇率变动趋势，判断存在大额外币现金余额及交易额的合理性。 | G28: √ | H28: √ | J28: √ | K28: √
D29: （二）银行存款
B30: D | C30: 6 | D30: 获取或编制银行存款余额明细表： （1）复核加计是否正确，并与总账数和日记账合计数核对是否相符； （2）检查非记账本位币银行存款的折算汇率及折算金额是否正确。 | E30: 是 | F30: =目录!E8&"、"&目录!E17 -> 1010-3-2、1010-11 | J30: √
C33: 7 | D33: 如果对银行账户的完整性存有疑虑，注册会计师应实施以下审计程序： | K33: √
D34: （1）了解并评价被审计单位与开立银行账户相关的内部控制的设计和执行。了解报告期内被审计单位开立账户的数量及分布，与被审计单位实际经营的需要进行比较，判断其合理性，关注是否存在越权开立账户等异常情形。 | H34: √ | J34: √ | K34: √
D35: （2）询问负责货币资金业务的相关人员（如出纳），了解账户的开立、使用、注销等情况。必要时，获取被审计单位已将全部银行账户信息提供给注册会计师的书面声明。如发现银行存款账户户名为个人，但记录在被审计单位账户清单或账簿中，考虑该个人与被审计单位的关系，并获取书面声明。 | H35: √ | J35: √ | K35: √
B36: B | D36: （3）注册会计师在企业人员陪同下到人民银行或基本存款账户开户行查询并打印《已开立银行结算账户清单》，观察银行办事人员的查询、打印过程，并检查被审计单位账面记录的银行人民币结算账户是否完整。 | E36: 是 | F36: =目录!E11 -> 1010-5 | H36: √
D37: （4）结合其他相关细节测试，关注交易相关单据中被审计单位的收（付）款银行账户是否均包含在注册会计师已获取的开立银行账户清单内。 | H37: √ | J37: √
D38: （5）如果对被审计单位外币银行账户的完整性存有疑虑，可以查阅被审计单位的公章使用登记，检查其中是否有使用公章申请开户的情况，如有，检查该账户是否已列入被审计单位提供的银行账户清单中；或者向负责保管网银密钥（UKey）的人员获取被审计单位开通网银的账户清单，实地观察该人员登录被审计单位网银系统，打印相关银行开立的所有银行账户清单，并与被审计单位管理层提供的信息进行比较，以检查其完整性。如可行，注册会计师可以考虑与被审计单位人员一同前往被审计单位所在地人民银行外汇管理局，现场查询被审计单位的外币银行账户情况。 | H38: √ | J38: √
B39: DAB | C39: 8 | D39: 计算银行存款累计余额应收利息收入，分析比较被审计单位银行存款应收利息收入与实际利息收入的差异是否恰当，评估利息收入的合理性，检查是否存在高息资金拆借，确认银行存款余额是否存在，利息收入是否已经完整记录。 会计监管风险提示第4号（证监办发[2012]89号）特别要求：对于IPO业务，注册会计师在执行与货币资金有关的实质性审计程序时，不应仅局限于银行函证、现金盘点和检查银行存款余额调节表等常规审计程序，还应该结合发行人申报期内的销售、采购交易等情况，适当运用分析性程序以识别风险：…（4）结合对利息收入和银行手续费的审计，分析发行人货币资金余额和交易的合理性。 | G39: √ | H39: √ | J39: √
C40: 9 | D40: 执行货币资金的分析程序，结合对其他项目的分析核验，判断货币资金项目的合理性。例如对上市公司货币资金余额持续较高、“存贷双高”等情形，应当将货币资金余额与利息收支、资金支出、资金使用计划、利润分配、同行业情况、手续费、控股股东相关情况等对比分析并评估其合理性，对异常情况进行调查。 | G40: √ | H40: √ | J40: √
B41: AC | C41: 10 | D41: 函证银行存款余额，编制银行函证结果汇总表，检查银行回函： （1）向被审计单位在本期存过款的银行发函，包括零账户和账户已结清的银行； （2）确定被审计单位账面余额与银行函证结果的差异，对不符事项作出适当处理。 会计监管风险提示第4号（证监办发[2012]89号）特别要求：对于IPO项目，在进行银行函证时，关注是否存在受限货币资金。 | E41: 是 | F41: =目录!E21 -> 1011 | G41: √ | I41: √
B42: C | C42: 11 | D42: 检查银行存款账户存款人是否为被审计单位，若存款人非被审计单位，应获取该账户户主和被审计单位的书面声明，确认资产负债表日是否需要调整。 会计监管风险提示第4号（证监办发[2012]89号）特别对于IPO业务，注册会计师在执行与货币资金有关的实质性审计程序时，不应仅局限于银行函证、现金盘点和检查银行存款余额调节表等常规审计程序，还应该结合发行人申报期内的销售、采购交易等情况，适当运用分析性程序以识别风险：（1）申报期内开户银行的数量及分布与发行人实际经营的需要是否一致；（2）银行账户的实际用途是否合理，尤其关注申报期内大额资金往来和新开账户；（3）申报期内注销账户原因，防止因发行人注销账户而降低注册会计师对该账户的风险预期等；（4）结合对利息收入和银行手续费的审计，分析发行人货币资金余额和交易的合理性。 | E42: 是 | F42: =目录!E11 -> 1010-5 | I42: √
B43: AB | C43: 12 | D43: 证监会14号公告第8项要求：发行人及相关中介机构应充分关注现金收付交易对发行人会计核算基础的不利影响。包括从外部获取期末资金流水与企业日记账、企业提供的对账单核对；核查现金销售金额及其占总销售额的比例，评估现金销售的风险；对大额和异常项目进行抽查 | E43: 是 | F43: =目录!E20 -> 1010-14 | G43: √ | H43: √
B44: E | C44: 13 | D44: 关注是否存在质押、冻结等对变现有限制或存在境外的款项。是否已做必要的调整和披露。 | E44: 是 | F44: =目录!E16 -> 1010-10 | K44: √
...

Sheet 1010-1
A1: << | B1: 货币资金科目审计调整分录 | I1: 索引号： | J1: =目录!E5 -> 1010-1
B2: =目录!G4&目录!J4&" "&目录!G5&目录!H5&" "&目录!G6&目录!H6&" "&目录!I5&目录!J5&目录!L5&" "&目录!I6&目录!J6&目录!L6 -> 被审计单位：钢力金属 会计期间：2024-1-1至2024-12-31 截止日期：2024-12-31 编制人：黄振通2025-1-23 复核人：王裕昆2025-2-10
B4: 分录序号 | C4: 调整事项说明 | D4: 报表科目 | E4: 二级科目 | F4: 三级科目 | G4: 明细项目 | H4: 调 整 金 额 | J4: 备注
H5: 借 方 | I5: 贷 方
B6: [START] | D6: =IF(ROUND((H6-I6),2)<>0,"调整分录不平",ROUND((H6-I6),2)) -> 0 | H6: =SUM(H7:H50) -> 0 | I6: =SUM(I7:I50) -> 0

Sheet 1010-2
A1: << | B1: 货币资金审定表 | G1: 索引号： | H1: =目录!E6 -> 1010-2
B2: =目录!G4&目录!J4&" "&目录!G5&目录!H5&" "&目录!G6&目录!H6&" "&目录!I5&目录!J5&目录!L5&" "&目录!I6&目录!J6&目录!L6 -> 被审计单位：钢力金属 会计期间：2024-1-1至2024-12-31 截止日期：2024-12-31 编制人：黄振通2025-1-23 复核人：王裕昆2025-2-10
A4: {=""} | B4: 项目 | C4: 期末未审数 | D4: 审计调整 | E4: 期末审定数 | F4: 期初审定数 | G4: 对比上期末变动额 | H4: 变动率
B5: 库存现金 | C5: ='1010-3-1'!H16 -> 0 | D5: =SUMIF('1010-1'!$D$7:$D$50,B5,'1010-1'!$H$7:$H$50)-SUMIF('1010-1'!$D$7:$D$50,B5,'1010-1'!$I$7:$I$50) -> 0 | E5: =C5+D5 -> 0 | F5: ='1010-3-1'!AM5 -> 0 | G5: =E5-F5 -> 0 | H5: =IFERROR(IF(F5<0,"不适用",G5/F5),"")
B6: 银行存款 | C6: ='1010-3-2'!O26 -> 215947.63 | D6: =SUMIF('1010-1'!$D$7:$D$50,B6,'1010-1'!$H$7:$H$50)-SUMIF('1010-1'!$D$7:$D$50,B6,'1010-1'!$I$7:$I$50) -> 0 | E6: =C6+D6 -> 215947.63 | F6: ='1010-3-2'!AM5 -> 48719.79 | G6: =E6-F6 -> 167227.84 | H6: =IFERROR(IF(F6<0,"不适用",G6/F6),"") -> 3.4324417
B7: 其他货币资金 | C7: ='1010-3-3'!O21 -> 2390600.1 | D7: =SUMIF('1010-1'!$D$7:$D$50,B7,'1010-1'!$H$7:$H$50)-SUMIF('1010-1'!$D$7:$D$50,B7,'1010-1'!$I$7:$I$50) -> 0 | E7: =C7+D7 -> 2390600.1 | F7: ='1010-3-3'!AM5 -> 2326906.7 | G7: =E7-F7 -> 63693.39 | H7: =IFERROR(IF(F7<0,"不适用",G7/F7),"") -> 0.027372558
B8: 合计 | C8: =SUM(C5:C7) -> 2606547.8 | D8: =SUM(D5:D7) -> 0 | E8: =SUM(E5:E7) -> 2606547.8 | F8: =SUM(F5:F7) -> 2375626.5 | G8: =SUM(G5:G7) -> 230921.23 | H8: — —
D9: ='1010-3-1'!J16+'1010-3-2'!Q26+'1010-3-3'!Q21-D8 -> 0 | E9: ='1010-3-1'!L16+'1010-3-2'!S26+'1010-3-3'!S21-E8 -> 0
B11: 审计说明：
B12: 1、获取企业明细账，并与总账核对一致。
B13: 2、已对库存现金及保险柜存放其他物品情况进行盘点，盘点情况详见“1010-4”。
B14: 3、对所有已开立账户进行函证，（审计结论），见“xxx”。
B15: 4、取得自基本户打印的已开立其他银行结算账户清单，经检查，（审计结论），见“1010-5”。
B16: 5、已获取定期银行存单，并根据所属银行、本金、到期日情况编制银行存单检查表，详见“1010-9”。
B17: 6、针对整个科目不实施发函程序的，请说明不发函原因：
B18: 7、……
B21: 审计调整： | C21: 无
B23: 审计结论： | C23: 经审计调整后，余额可以确认。
B27: 编制说明：
B28: “审计说明”至少需要说明该科目核算内容、增减变动的主要原因、所做的审计工作等内容。
C31: 无
C32: 参见1010-1
C36: 经审计调整后，余额可以确认。
C37: 经审计后，无调整事项，余额可以确认。
C38: 经审计调整后，发生额可以确认。
C39: 经审计后，无调整事项，发生额可以确认。
C40: 经审计测试后，未见异常。
C41: 经我们审计，除上述说明事项外，未发现其他重大异常。
C42: [自定义审计结论1…]
C43: [自定义审计结论2…]
C44: [自定义审计结论3…]

Sheet 1010-3-1
A1: << | B1: 库存现金明细表 | L1: 索引号： | M1: =目录!E7 -> 1010-3-1
B2: =目录!G4&目录!J4&" "&目录!G5&目录!H5&" "&目录!G6&目录!H6&" "&目录!I5&目录!J5&目录!L5&" "&目录!I6&目录!J6&目录!L6 -> 被审计单位：钢力金属 会计期间：2024-1-1至2024-12-31 截止日期：2024-12-31 编制人：黄振通2025-1-23 复核人：王裕昆2025-2-10
AK3: 不设打印区域：
B4: 序号 | C4: 所属单位 | D4: 币种 | E4: 期初余额 | G4: 调整前期末余额 | I4: 审计调整 | K4: 期末审定数 | M4: 备注 | AK4: 期初余额 | AL4: 期初审计调整 | AM4: 期初审定数
E5: 原币 | F5: 本位币 | G5: 原币 | H5: 本位币 | I5: 原币 | J5: 本位币 | K5: 原币 | L5: 本位币 | AK5: =F16 -> 0 | AM5: =AK5+AL5 -> 0
A6: {=""} | B6: 1 | K6: =G6+I6 -> 0 | L6: =H6+J6 -> 0
B7: 2 | K7: =G7+I7 -> 0 | L7: =H7+J7 -> 0 | AK7: 期初数调整说明：
B8: 3 | K8: =G8+I8 -> 0 | L8: =H8+J8 -> 0 | AK8: √ | AL8: 经审核，企业已经按照上年度审计报告进行了跟调，我们认可期初审定数，因此本期不涉及期初审计调整；
B9: 4 | K9: =G9+I9 -> 0 | L9: =H9+J9 -> 0 | AK9: × | AL9: 经审核，本年度存在会计政策变更事项，需要对期初数进行调整，因此本期对上期审定数作出如下调整（如果笔数过多，可索引至TB）：
B10: 5 | K10: =G10+I10 -> 0 | L10: =H10+J10 -> 0 | AK10: × | AL10: 经审核，本年度存在前期差错更正事项，需要对期初数进行调整，因此本期对上期审定数作出如下调整（如果笔数过多，可索引至TB）：
B11: 6 | K11: =G11+I11 -> 0 | L11: =H11+J11 -> 0
B12: 7 | K12: =G12+I12 -> 0 | L12: =H12+J12 -> 0 | AK12: 项目 | AL12: 上期末审定数 | AM12: 重要会计政策变更影响额 | AN12: 重要前期差错 | AO12: 期初审定数
B13: 8 | K13: =G13+I13 -> 0 | L13: =H13+J13 -> 0 | AK13: 库存现金 | AO13: =AL13+AM13+AN13 -> 0
B14: 9 | K14: =G14+I14 -> 0 | L14: =H14+J14 -> 0 | AK14: =IF(AK5<>AL13,"说明：企业未按照上年度审计报告跟调。","说明：企业已按照上年度审计报告跟调。") -> 说明：企业已按照上年度审计报告跟调。 | AO14: =AM5-AO13 -> 0 | AP14: 请注意检查是否漏填报“上期末审定数”！！！
B15: 10 | K15: =G15+I15 -> 0 | L15: =H15+J15 -> 0
B16: 合计 | E16: =SUM(E6:E15) -> 0 | F16: =SUM(F6:F15) -> 0 | G16: =SUM(G6:G15) -> 0 | H16: =SUM(H6:H15) -> 0 | I16: =SUM(I6:I15) -> 0 | J16: =SUM(J6:J15) -> 0 | K16: =SUM(K6:K15) -> 0 | L16: =SUM(L6:L15) -> 0 | AL16: 调整事项说明 | AM16: 报表科目 | AN16: 二级科目 | AO16: 三级科目 | AP16: 明细项目 | AQ16: 调 整 金 额 | AS16: 备注
AQ17: 借 方 | AR17: 贷 方
B18: 审计说明：
B19: 1、已对大额现金进行抽查，详见“”；
B22: 编制说明：
B23: 1、会计监管风险提示第4号（证监办发[2012]89号）特别要求：对于IPO业务，审计人员在对发行人大额现金收支交易进行审计时，应当：(1 )关注大额现金使用范围是否符合《现金管理暂行条例》的规定；(2 )以收取现金方式实现销售的，应核对付款方和付款金额与合同、订单、出库单是否一致，以确定款项确实由客户支付；(3)必要时，向现金交易客户函证申报期内各期收入金额，以评估现金收入的发生和完整性认定是否恰当。(4 )结合对利息收入和银行手续费的审计，分析发行人货币资金余额和交易的合理性。

Sheet 1010-3-2
A1: << | B1: 银行存款明细表 | K1: 期初未审数 | R1: 索引号： | S1: =目录!E8 -> 1010-3-2
B2: =目录!G4&目录!J4&" "&目录!G5&目录!H5&" "&目录!G6&目录!H6&" "&目录!I5&目录!J5&目录!L5&" "&目录!I6&目录!J6&目录!L6 -> 被审计单位：钢力金属 会计期间：2024-1-1至2024-12-31 截止日期：2024-12-31 编制人：黄振通2025-1-23 复核人：王裕昆2025-2-10
AK3: 不设打印区域：
A4: {=""} | B4: 序号 | C4: 所属单位 | D4: 开户银行 | E4: 银行账号 | F4: 币种 | G4: 账户性质 | H4: 期初余额 | J4: 本期借方 | L4: 本期贷方 | N4: 调整前期末余额 | P4: 审计调整 | R4: 期末审定数 | AK4: 期初余额 | AL4: 期初审计调整 | AM4: 期初审定数
H5: 原币 | I5: 本位币 | J5: 原币 | K5: 本位币 | L5: 原币 | M5: 本位币 | N5: 原币 | O5: 本位币 | P5: 原币 | Q5: 本位币 | R5: 原币 | S5: 本位币 | AK5: =I26 -> 48719.79 | AM5: =AK5+AL5 -> 48719.79
B6: 1 | C6: 钢力金属 | D6: 工行广州市大德路支行4206 | E6: 3602003819200314206 | F6: 人民币 | G6: 一般户 | H6: 22831.98 | I6: 22831.98 | J6: 23825.8 | K6: 23825.8 | L6: 774 | M6: 774 | N6: =H6+J6-L6 -> 45883.78 | O6: =I6+K6-M6 -> 45883.78 | R6: =N6+P6 -> 45883.78 | S6: =ROUND(O6+Q6,2) -> 45883.78
B7: 2 | C7: 钢力金属 | D7: 建行广州大德路支行3210 | E7: 44001420301053013210 | F7: 人民币 | G7: 基本户 | H7: 25887.81 | I7: 25887.81 | J7: 6407445.6 | K7: 6407445.6 | L7: 6263269.5 | M7: 6263269.5 | N7: =H7+J7-L7 -> 170063.85 | O7: =I7+K7-M7 -> 170063.85 | R7: =N7+P7 -> 170063.85 | S7: =ROUND(O7+Q7,2) -> 170063.85 | AK7: 期初数调整说明：
B8: 3 | N8: =H8+J8-L8 -> 0 | O8: =I8+K8-M8 -> 0 | R8: =N8+P8 -> 0 | S8: =ROUND(O8+Q8,2) -> 0 | AK8: √ | AL8: 经审核，企业已经按照上年度审计报告进行了跟调，我们认可期初审定数，因此本期不涉及期初审计调整；
B9: 4 | N9: =H9+J9-L9 -> 0 | O9: =I9+K9-M9 -> 0 | R9: =N9+P9 -> 0 | S9: =ROUND(O9+Q9,2) -> 0 | AK9: × | AL9: 经审核，本年度存在会计政策变更事项，需要对期初数进行调整，因此本期对上期审定数作出如下调整（如果笔数过多，可索引至TB）：
B10: 5 | N10: =H10+J10-L10 -> 0 | O10: =I10+K10-M10 -> 0 | R10: =N10+P10 -> 0 | S10: =ROUND(O10+Q10,2) -> 0 | AK10: × | AL10: 经审核，本年度存在前期差错更正事项，需要对期初数进行调整，因此本期对上期审定数作出如下调整（如果笔数过多，可索引至TB）：
B11: 6 | N11: =H11+J11-L11 -> 0 | O11: =I11+K11-M11 -> 0 | R11: =N11+P11 -> 0 | S11: =ROUND(O11+Q11,2) -> 0
B12: 7 | N12: =H12+J12-L12 -> 0 | O12: =I12+K12-M12 -> 0 | R12: =N12+P12 -> 0 | S12: =ROUND(O12+Q12,2) -> 0 | AK12: 项目 | AL12: 上期末审定数 | AM12: 重要会计政策变更影响额 | AN12: 重要前期差错 | AO12: 期初审定数
B13: 8 | N13: =H13+J13-L13 -> 0 | O13: =I13+K13-M13 -> 0 | R13: =N13+P13 -> 0 | S13: =ROUND(O13+Q13,2) -> 0 | AK13: 银行存款 | AL13: 48719.79 | AO13: =AL13+AM13+AN13 -> 48719.79
B14: 9 | N14: =H14+J14-L14 -> 0 | O14: =I14+K14-M14 -> 0 | R14: =N14+P14 -> 0 | S14: =ROUND(O14+Q14,2) -> 0 | AK14: =IF(AK5<>AL13,"说明：企业未按照上年度审计报告跟调。","说明：企业已按照上年度审计报告跟调。") -> 说明：企业已按照上年度审计报告跟调。 | AO14: =AM5-AO13 -> 0 | AP14: 请注意检查是否漏填报“上期末审定数”！！！
B15: 10 | N15: =H15+J15-L15 -> 0 | O15: =I15+K15-M15 -> 0 | R15: =N15+P15 -> 0 | S15: =ROUND(O15+Q15,2) -> 0
B16: 11 | N16: =H16+J16-L16 -> 0 | O16: =I16+K16-M16 -> 0 | R16: =N16+P16 -> 0 | S16: =ROUND(O16+Q16,2) -> 0 | AL16: 调整事项说明 | AM16: 报表科目 | AN16: 二级科目 | AO16: 三级科目 | AP16: 明细项目 | AQ16: 调 整 金 额 | AS16: 备注
B17: 12 | N17: =H17+J17-L17 -> 0 | O17: =I17+K17-M17 -> 0 | R17: =N17+P17 -> 0 | S17: =ROUND(O17+Q17,2) -> 0 | AQ17: 借 方 | AR17: 贷 方
B18: 13 | N18: =H18+J18-L18 -> 0 | O18: =I18+K18-M18 -> 0 | R18: =N18+P18 -> 0 | S18: =ROUND(O18+Q18,2) -> 0
B19: 14 | N19: =H19+J19-L19 -> 0 | O19: =I19+K19-M19 -> 0 | R19: =N19+P19 -> 0 | S19: =ROUND(O19+Q19,2) -> 0
B20: 15 | N20: =H20+J20-L20 -> 0 | O20: =I20+K20-M20 -> 0 | R20: =N20+P20 -> 0 | S20: =ROUND(O20+Q20,2) -> 0
B21: 16 | N21: =H21+J21-L21 -> 0 | O21: =I21+K21-M21 -> 0 | R21: =N21+P21 -> 0 | S21: =ROUND(O21+Q21,2) -> 0
B22: 17 | N22: =H22+J22-L22 -> 0 | O22: =I22+K22-M22 -> 0 | R22: =N22+P22 -> 0 | S22: =ROUND(O22+Q22,2) -> 0
B23: 18 | N23: =H23+J23-L23 -> 0 | O23: =I23+K23-M23 -> 0 | R23: =N23+P23 -> 0 | S23: =ROUND(O23+Q23,2) -> 0
B24: 19 | N24: =H24+J24-L24 -> 0 | O24: =I24+K24-M24 -> 0 | R24: =N24+P24 -> 0 | S24: =ROUND(O24+Q24,2) -> 0
B25: 20 | N25: =H25+J25-L25 -> 0 | O25: =I25+K25-M25 -> 0 | R25: =N25+P25 -> 0 | S25: =ROUND(O25+Q25,2) -> 0
B26: 合计 | H26: =SUM(H6:H25) -> 48719.79 | I26: =SUM(I6:I25) -> 48719.79 | J26: =SUM(J6:J25) -> 6431271.4 | K26: =SUM(K6:K25) -> 6431271.4 | L26: =SUM(L6:L25) -> 6264043.5 | M26: =SUM(M6:M25) -> 6264043.5 | N26: =SUM(N6:N25) -> 215947.63 | O26: =SUM(O6:O25) -> 215947.63 | ... S26: =SUM(S6:S25) -> 215947.63
B28: 审计说明：
B29: 经审计，期初数与上年审定数一致，本期银行存款余额与银行对账单核对，无未达账项。
B34: 编制说明：
B35: 1、银行存款审计应通过银行取得企业《开户卡资料》予以核对。目前银行开户卡资料包括开户、销户、正常使用等情况。审计人员应记录开户资料的核对情况。
B36: 2、审计人员注意核对对账单等资料与明细表中期末余额是否一致，如果不一致应进行说明。

Sheet 1010-3-3
A1: << | B1: 其他货币资金明细表 | R1: 索引号： | S1: =目录!E9 -> 1010-3-3
B2: =目录!G4&目录!J4&" "&目录!G5&目录!H5&" "&目录!G6&目录!H6&" "&目录!I5&目录!J5&目录!L5&" "&目录!I6&目录!J6&目录!L6 -> 被审计单位：钢力金属 会计期间：2024-1-1至2024-12-31 截止日期：2024-12-31 编制人：黄振通2025-1-23 复核人：王裕昆2025-2-10
AK3: 不设打印区域：
B4: 序号 | C4: 所属单位 | D4: 开户银行 | E4: 银行账号 | F4: 币种 | G4: 账户性质 | H4: 期初余额 | J4: 本期借方 | L4: 本期贷方 | N4: 调整前期末余额 | P4: 审计调整 | R4: 期末审定数 | AK4: 期初余额 | AL4: 期初审计调整 | AM4: 期初审定数
H5: 原币 | I5: 本位币 | J5: 原币 | K5: 本位币 | L5: 原币 | M5: 本位币 | N5: 原币 | O5: 本位币 | P5: 原币 | Q5: 本位币 | R5: 原币 | S5: 本位币 | AK5: =I21 -> 2326906.7 | AM5: =AK5+AL5 -> 2326906.7
A6: {=""} | B6: 1 | C6: 钢力总厂 | D6: 中国工商银行广州银山支行1720 | E6: 3602046240000011720 | F6: 人民币 | G6: 专用户 | H6: 1379736.5 | I6: 1379736.5 | J6: 2563.22 | K6: 2563.22 | L6: =0 -> 0 | M6: =0 -> 0 | N6: =H6+J6-L6 -> 1382299.7 | O6: =I6+K6-M6 -> 1382299.7 | R6: =N6+P6 -> 1382299.7 | S6: =ROUND(O6+Q6,2) -> 1382299.7
B7: 2 | C7: 钢力总厂 | D7: 建行广州市仓边路支行6461 | E7: 440420315014574206461 | F7: 人民币 | G7: 专用户 | H7: 947170.27 | I7: 947170.27 | J7: 61130.17 | K7: 61130.17 | L7: =0 -> 0 | M7: =0 -> 0 | N7: =H7+J7-L7 -> 1008300.4 | O7: =I7+K7-M7 -> 1008300.4 | R7: =N7+P7 -> 1008300.4 | S7: =ROUND(O7+Q7,2) -> 1008300.4 | AK7: 期初数调整说明：
B8: 3 | N8: =H8+J8-L8 -> 0 | O8: =I8+K8-M8 -> 0 | R8: =N8+P8 -> 0 | S8: =ROUND(O8+Q8,2) -> 0 | AK8: √ | AL8: 经审核，企业已经按照上年度审计报告进行了跟调，我们认可期初审定数，因此本期不涉及期初审计调整；
B9: 4 | N9: =H9+J9-L9 -> 0 | O9: =I9+K9-M9 -> 0 | R9: =N9+P9 -> 0 | S9: =ROUND(O9+Q9,2) -> 0 | AK9: × | AL9: 经审核，本年度存在会计政策变更事项，需要对期初数进行调整，因此本期对上期审定数作出如下调整（如果笔数过多，可索引至TB）：
B10: 5 | N10: =H10+J10-L10 -> 0 | O10: =I10+K10-M10 -> 0 | R10: =N10+P10 -> 0 | S10: =ROUND(O10+Q10,2) -> 0 | AK10: × | AL10: 经审核，本年度存在前期差错更正事项，需要对期初数进行调整，因此本期对上期审定数作出如下调整（如果笔数过多，可索引至TB）：
B11: 6 | N11: =H11+J11-L11 -> 0 | O11: =I11+K11-M11 -> 0 | R11: =N11+P11 -> 0 | S11: =ROUND(O11+Q11,2) -> 0
B12: 7 | N12: =H12+J12-L12 -> 0 | O12: =I12+K12-M12 -> 0 | R12: =N12+P12 -> 0 | S12: =ROUND(O12+Q12,2) -> 0 | AK12: 项目 | AL12: 上期末审定数 | AM12: 重要会计政策变更影响额 | AN12: 重要前期差错 | AO12: 期初审定数
B13: 8 | N13: =H13+J13-L13 -> 0 | O13: =I13+K13-M13 -> 0 | R13: =N13+P13 -> 0 | S13: =ROUND(O13+Q13,2) -> 0 | AK13: 其他货币资金 | AL13: 2326906.7 | AO13: =AL13+AM13+AN13 -> 2326906.7
B14: 9 | N14: =H14+J14-L14 -> 0 | O14: =I14+K14-M14 -> 0 | R14: =N14+P14 -> 0 | S14: =ROUND(O14+Q14,2) -> 0 | AK14: =IF(AK5<>AL13,"说明：企业未按照上年度审计报告跟调。","说明：企业已按照上年度审计报告跟调。") -> 说明：企业已按照上年度审计报告跟调。 | AO14: =AM5-AO13 -> 0 | AP14: 请注意检查是否漏填报“上期末审定数”！！！
B15: 10 | N15: =H15+J15-L15 -> 0 | O15: =I15+K15-M15 -> 0 | R15: =N15+P15 -> 0 | S15: =ROUND(O15+Q15,2) -> 0
B16: 11 | N16: =H16+J16-L16 -> 0 | O16: =I16+K16-M16 -> 0 | R16: =N16+P16 -> 0 | S16: =ROUND(O16+Q16,2) -> 0 | AL16: 调整事项说明 | AM16: 报表科目 | AN16: 二级科目 | AO16: 三级科目 | AP16: 明细项目 | AQ16: 调 整 金 额 | AS16: 备注
B17: 12 | N17: =H17+J17-L17 -> 0 | O17: =I17+K17-M17 -> 0 | R17: =N17+P17 -> 0 | S17: =ROUND(O17+Q17,2) -> 0 | AQ17: 借 方 | AR17: 贷 方
B18: 13 | N18: =H18+J18-L18 -> 0 | O18: =I18+K18-M18 -> 0 | R18: =N18+P18 -> 0 | S18: =ROUND(O18+Q18,2) -> 0
B19: 14 | N19: =H19+J19-L19 -> 0 | O19: =I19+K19-M19 -> 0 | R19: =N19+P19 -> 0 | S19: =ROUND(O19+Q19,2) -> 0
B20: 15 | N20: =H20+J20-L20 -> 0 | O20: =I20+K20-M20 -> 0 | R20: =N20+P20 -> 0 | S20: =ROUND(O20+Q20,2) -> 0
B21: 合计 | H21: =SUM(H6:H20) -> 2326906.7 | I21: =SUM(I6:I20) -> 2326906.7 | J21: =SUM(J6:J20) -> 63693.39 | K21: =SUM(K6:K20) -> 63693.39 | L21: =SUM(L6:L20) -> 0 | M21: =SUM(M6:M20) -> 0 | N21: =SUM(N6:N20) -> 2390600.1 | O21: =SUM(O6:O20) -> 2390600.1 | ... S21: =SUM(S6:S20) -> 2390600.1
B23: 审计说明：
B24: 经审计，期初数据与上年审定数一致，账户性质均为住房基金户，未发现其他异常情况。
B29: 编制说明：
B30: 1、审计人员注意核对对账单等资料与明细表中期末余额是否一致，如果不一致应进行说明。

Sheet 1010-4
A1: << | B1: 保险柜检查记录表 | M1: 索引号： | N1: =目录!E10 -> 1010-4
B2: =目录!G4&目录!J4&" "&目录!G5&目录!H5&" "&目录!G6&目录!H6&" "&目录!I5&目录!J5&目录!L5&" "&目录!I6&目录!J6&目录!L6 -> 被审计单位：钢力金属 会计期间：2024-1-1至2024-12-31 截止日期：2024-12-31 编制人：黄振通2025-1-23 复核人：王裕昆2025-2-10
B4: 盘点单位 | C4: =目录!H4 -> 广州钢力金属制品总厂有限公司 | H4: 审计基准日 | I4: =目录!H6 -> 2024-12-31
B5: 会计主管 | H5: 结账日期
B6: 出纳人员 | H6: 盘点日期
B7: 盘点人员 | H7: 监盘人员
B8: 一、现金检查盘点记录 | H8: 二、有价证券盘点记录 | J8: 三、尚未记账的收入支出凭证 | M8: 四、其他在保险柜存储的物品
B9: 项目 | D9: 项次 | E9: 人民币 | F9: 某外币1 | G9: 某外币2 | H9: 有价证券名称 | I9: 数量 | J9: 项目 | K9: 张数 | L9: 金额 | M9: 名称 | N9: 数量
B10: 盘点实有库存现金数额 | D10: ①
B11: 上一日账面库存余额 | D11: ②
B12: 盘点日未记账传票收入金额 | D12: ③
B13: 盘点日未记账传票支出金额 | D13: ④
B14: 盘点日账面应有金额 | D14: ⑤=②+③-④ | E14: =E11+E12-E13 -> 0 | F14: =F11+F12-F13 -> 0 | G14: =G11+G12-G13 -> 0
B15: 盘点日应有与实有差异 | D15: ⑥=⑤-① | E15: =E14-E10 -> 0 | F15: =F14-F10 -> 0 | G15: =G14-G10 -> 0
B16: 差异原因分析 | C16: 1
C17: 2
C18: 3
C19: 4
B20: 追溯调整 | C20: 报表日至审计日库存现金付出总额 | D20: ⑦
C21: 报表日至审计日库存现金收入总额 | D21: ⑧
C22: 报表日库存现金应有余额 | D22: ⑨=⑤+⑦-⑧ | E22: =E14+E20-E21 -> 0 | F22: =F14+F20-F21 -> 0 | G22: =G14+G20-G21 -> 0
C23: 报表日账面汇率 | D23: ⑩
C24: 报表日余额折合本位币金额 | D24: ⑾=⑨*⑩ | E24: =E22*E23 -> 0 | F24: =F22*F23 -> 0 | G24: =G22*G23 -> 0
B25: 本位币合计 | E25: =SUM(E24:G24) -> 0 | H25: 合计 | I25: =SUM(I10:I24) -> 0 | K25: =SUM(K10:K24) -> 0 | L25: =SUM(L10:L24) -> 0 | N25: =SUM(N10:N24) -> 0
B27: 审计说明：
B31: 编制说明：
B32: 1、本底稿需打印，并由相关人员签字确认（可直接索引至纸质底稿）；
B33: 2、表中的“未记账传票收入、支出金额”应按盘点日尚未记账的现金收入和支出的金额进行填列；
B34: 3、本表中的“实点金额”按“清点现金”的合计数填列；
B35: 4、本表中的“审计截止日至现金盘点日的支出和收入，按实际支出和收入的现金金额填列；
B36: 5、本表中的“差异”按审计截止日账面应结存金额与审计截止日账面余额的差异填列；
B37: 6、 如有外币可按本表格式另行填列，并测算折算本位币的正确性。

Sheet 1010-5
A1: << | B1: 已开立银行账户清单与账面银行账户双向核对 | M1: 索引号： | N1: =目录!E11 -> 1010-5
B2: =目录!G4&目录!J4&" "&目录!G5&目录!H5&" "&目录!G6&目录!H6&" "&目录!I5&目录!J5&目录!L5&" "&目录!I6&目录!J6&目录!L6 -> 被审计单位：钢力金属 会计期间：2024-1-1至2024-12-31 截止日期：2024-12-31 编制人：黄振通2025-1-23 复核人：王裕昆2025-2-10
B4: 序号 | C4: 所属单位 | D4: 开户清单列示信息 | J4: 账面银行账户 | N4: 两者是否一致
D5: 开户银行 | E5: 账号 | F5: 币种 | G5: 开户时间 | H5: 销户日期 | I5: 目前状态 | J5: 所属单位 | K5: 开户银行 | L5: 账号 | M5: 币种
B6: 1 | C6: 钢力金属 | D6: 中国工商银行股份有限公司广州宝华支行 | E6: 3602010909000402225 | F6: 人民币 | G6: 2005年05月18日 | H6: 2014年12月02日 | I6: 撤销
B7: 2 | C7: 钢力金属 | D7: 招商银行股份有限公司广州东风支行 | E7: 20098108011000 | F7: 人民币 | G7: 2005年07月18日 | H7: 2015年03月31日 | I7: 撤销
B8: 3 | C8: 钢力金属 | D8: 中国工商银行股份有限公司广州大德路支行 | E8: 3602003819200314206 | F8: 人民币 | G8: 2014年10月11日 | I8: 正常 | J8: 钢力金属 | K8: 工行广州市大德路支行4206 | L8: 3602003819200314206 | M8: 人民币 | N8: 是
B9: 4 | C9: 钢力金属 | D9: 中国建设银行股份有限公司广州大德路支行 | E9: 44001420301053013210 | F9: 人民币 | G9: 2014年12月25日 | I9: 正常 | J9: 钢力金属 | K9: 建行广州大德路支行3210 | L9: 44001420301053013210 | M9: 人民币 | N9: 是
B29: 审计说明：
B30: 1、说明开户清单有但账面未记录的原因：
B32: 2、说明账面有记录但开户清单无的原因：
B35: 编制说明：
B36: 针对外币账户我们已向负责保管网银密钥（U key）的出纳获取被审计单位开通网银的账户清单，实地观察出纳登录被审计单位网银系统，查阅相关银行开立的所有银行账户清单，与被审计单位提供的开户台账信息进行比较。

Sheet 1010-6
A1: << | B1: 银行账户网银核查情况表 | N1: 索引号： | O1: =目录!E12 -> 1010-6
B2: =目录!G4&目录!J4&" "&目录!G5&目录!H5&" "&目录!G6&目录!H6&" "&目录!I5&目录!J5&目录!L5&" "&目录!I6&目录!J6&目录!L6 -> 被审计单位：钢力金属 会计期间：2024-1-1至2024-12-31 截止日期：2024-12-31 编制人：黄振通2025-1-23 复核人：王裕昆2025-2-10
B4: 序号 | C4: 所属单位 | D4: 开户行 | E4: 账号 | F4: 币种 | G4: 账户性质 | H4: 账面期末余额 | I4: 网银记录余额 | J4: 差异 | K4: 账面记录是否受限 | L4: 网银记录是否受限 | M4: 账面记录与网银记录是否一致 | N4: 备注 | O4: 现场查看网银记录截图索引
J5: =H5-I5 -> 0
J6: =H6-I6 -> 0
J7: =H7-I7 -> 0
J8: =H8-I8 -> 0
J9: =H9-I9 -> 0
J10: =H10-I10 -> 0
J11: =H11-I11 -> 0
J12: =H12-I12 -> 0
J13: =H13-I13 -> 0
J14: =H14-I14 -> 0
J15: =H15-I15 -> 0
B17: 审计说明：
B23: 编制说明：
B24: 针对账户不在《已开立银行结算账户清单》上列示或无法获取纸质对账单的情况，项目组采取以下措施核实外币账户的完整性：向负责保管网银密钥（U key）的出纳获取被审计单位开通网银的账户清单，实地观察出纳登录被审计单位网银系统，查阅相关银行开立的所有银行账户清单，与被审计单位提供的开户台账信息进行比较，核实网银记录的金额和账面是否一致。

Sheet 1010-7
A1: << | B1: 货币资金截止性测试表 | G1: 索引号： | H1: =目录!E13 -> 1010-7
B2: 被审计单位：ABC公司 会计期间：2024-1-1至2024-12-31 截止日期：2024-12-31 编制人：DDD2025-1-23 复核人：EEE2025-2-10
B4: 一、测试目的 | D4: 确定货币资金期末截止性是否正确；是否存在大额跨期项目。
B6: 二、测试步骤 | D6: 选择资产负债表日前后15天大额非银行间转账的银行收支业务执行截止测试（提示：一般情况下截止测试统一选择前后15天的凭证进行测试，如果前后15天凭证金额均偏小，或者在测试过程已发现有跨期现象，可修改为选择前后30天的凭证记录进行测试，请根据样本情况修改日期）
B8: 三、测试结果 | D8: 经测试，未见跨期入账现象。
B11: 所属单位 | C11: 日期 | D11: 凭证号 | E11: 内容 | F11: 对应科目 | G11: 金额 | H11: 是否跨期
H12: 是（√）否（×）
B13: ABC公司 | C13: 2024-12-24 | D13: 2024-12记-0003 | E13: 支付ABC公司2024年财产险保险年费 | F13: 银行存款\建设银行 | G13: 6270.42 | H13: ×
B24: 截止日前
B25: ---------------------------------------------------------------
B26: 截止日期：2024 年 12 月31 日
B27: --------------------------------------------------------------------
B28: 截止日后

Sheet 1010-8
A1: << | B1: 银行余额调节以及未达账项汇总表 | L1: 索引号： | M1: =目录!E14 -> 1010-8
B2: =目录!G4&目录!J4&" "&目录!G5&目录!H5&" "&目录!G6&目录!H6&" "&目录!I5&目录!J5&目录!L5&" "&目录!I6&目录!J6&目录!L6 -> 被审计单位：钢力金属 会计期间：2024-1-1至2024-12-31 截止日期：2024-12-31 编制人：黄振通2025-1-23 复核人：王裕昆2025-2-10
B4: 序号 | C4: 所属单位 | D4: 开户行名称 | E4: 账号 | F4: 币种 | G4: 本期账面余额 | H4: 加：银行已收 企业未收 | I4: 减：银行已付 企业未付 | J4: 加：企业已付 银行未付 | K4: 减：企业已收 银行未收 | L4: 本期账面余额对账单余额 | M4: 对账单&未达账项余额调节表索引
B5: 银行存款合计 | G5: =SUM(G6:G15) -> 215947.63 | H5: =SUM(H6:H15) -> 0 | I5: =SUM(I6:I15) -> 0 | J5: =SUM(J6:J15) -> 0 | K5: =SUM(K6:K15) -> 0 | L5: =SUM(L6:L15) -> 215947.63
B6: 1 | C6: 钢力金属 | D6: 工行广州市大德路支行4206 | E6: 3602003819200314206 | F6: 人民币 | G6: 45883.78 | L6: =G6+H6-I6+J6-K6 -> 45883.78
B7: 2 | C7: 钢力金属 | D7: 建行广州大德路支行3210 | E7: 44001420301053013210 | F7: 人民币 | G7: 170063.85 | L7: =G7+H7-I7+J7-K7 -> 170063.85
B8: 3 | L8: =G8+H8-I8+J8-K8 -> 0
B9: 4 | L9: =G9+H9-I9+J9-K9 -> 0
B10: 5 | L10: =G10+H10-I10+J10-K10 -> 0
B11: 6 | L11: =G11+H11-I11+J11-K11 -> 0
B12: 7 | L12: =G12+H12-I12+J12-K12 -> 0
B13: 8 | L13: =G13+H13-I13+J13-K13 -> 0
B14: 9 | L14: =G14+H14-I14+J14-K14 -> 0
B15: 10 | L15: =G15+H15-I15+J15-K15 -> 0
B16: 其他货币资金合计 | G16: =SUM(G17:G21) -> 2390600.1 | H16: =SUM(H17:H21) -> 0 | I16: =SUM(I17:I21) -> 0 | J16: =SUM(J17:J21) -> 0 | K16: =SUM(K17:K21) -> 0 | L16: =SUM(L17:L21) -> 2390600.1
B17: 1 | C17: 钢力总厂 | D17: 中国工商银行广州银山支行1720 | E17: 3602046240000011720 | F17: 人民币 | G17: 1382299.7 | L17: =G17+H17-I17+J17-K17 -> 1382299.7
B18: 2 | C18: 钢力总厂 | D18: 建行广州市仓边路支行6461 | E18: 440420315014574206461 | F18: 人民币 | G18: 1008300.4 | L18: =G18+H18-I18+J18-K18 -> 1008300.4
B19: 3 | L19: =G19+H19-I19+J19-K19 -> 0
B20: 4 | L20: =G20+H20-I20+J20-K20 -> 0
B21: 5 | L21: =G21+H21-I21+J21-K21 -> 0
B24: 审计说明：
B25: 经审计，各开户银行银行存款账面余额与银行对账单余额一致。

Sheet 1010-9
A1: << | B1: 银行存单检查表 | T1: 索引号： | U1: =目录!E15 -> 1010-9
B2: =目录!G4&目录!J4&" "&目录!G5&目录!H5&" "&目录!G6&目录!H6&" "&目录!I5&目录!J5&目录!L5&" "&目录!I6&目录!J6&目录!L6 -> 被审计单位：钢力金属 会计期间：2024-1-1至2024-12-31 截止日期：2024-12-31 编制人：黄振通2025-1-23 复核人：王裕昆2025-2-10
B4: 开户银行 | C4: 所属单位 | D4: 账号 | E4: 币种 | F4: 转存标识 | G4: 能否转让 | H4: 能否提前支取 | I4: 能否提前赎回 | J4: 存入日期 | K4: 到期日 | L4: 存期/期限 | M4: 年利率 | N4: 年末存单金额 | O4: 年末账面余额 | P4: 差异 | Q4: 利息收入 | R4: 是否查见原件（√） | S4: 是否质押 （√） | T4: 索引 | U4: 备注
B5: 1.定期存款
G6: / | P6: =N6-O6 -> 0 | Q6: =ROUND(N6*M6*(K6-J6)/360,2) -> 0
G7: / | P7: =N7-O7 -> 0 | Q7: =ROUND(N7*M7*(K7-J7)/360,2) -> 0
G8: / | P8: =N8-O8 -> 0 | Q8: =ROUND(N8*M8*(K8-J8)/360,2) -> 0
G9: / | P9: =N9-O9 -> 0 | Q9: =ROUND(N9*M9*(K9-J9)/360,2) -> 0
G10: / | P10: =N10-O10 -> 0 | Q10: =ROUND(N10*M10*(K10-J10)/360,2) -> 0
G11: / | P11: =N11-O11 -> 0 | Q11: =ROUND(N11*M11*(K11-J11)/360,2) -> 0
G12: / | P12: =N12-O12 -> 0 | Q12: =ROUND(N12*M12*(K12-J12)/360,2) -> 0
G13: / | P13: =N13-O13 -> 0 | Q13: =ROUND(N13*M13*(K13-J13)/360,2) -> 0
B14: 2.大额存单
F15: / | P15: =N15-O15 -> 0 | Q15: =ROUND(N15*M15*(K15-J15)/360,2) -> 0
F16: / | P16: =N16-O16 -> 0 | Q16: =ROUND(N16*M16*(K16-J16)/360,2) -> 0
F17: / | P17: =N17-O17 -> 0 | Q17: =ROUND(N17*M17*(K17-J17)/360,2) -> 0
F18: / | P18: =N18-O18 -> 0 | Q18: =ROUND(N18*M18*(K18-J18)/360,2) -> 0
F19: / | P19: =N19-O19 -> 0 | Q19: =ROUND(N19*M19*(K19-J19)/360,2) -> 0
F20: / | P20: =N20-O20 -> 0 | Q20: =ROUND(N20*M20*(K20-J20)/360,2) -> 0
F21: / | P21: =N21-O21 -> 0 | Q21: =ROUND(N21*M21*(K21-J21)/360,2) -> 0
B22: 合 计 | N22: =SUM(N5:N21) -> 0 | O22: =SUM(O5:O21) -> 0 | P22: =SUM(P5:P21) -> 0 | Q22: =SUM(Q5:Q21) -> 0
B24: 审计说明：
B25: 1、逐项说明各存单的存款期限及其质押、担保或其他限制情况，有无存在提前支取情况：……
B26: 2、若部分存单已函证，请说明函证情况索引至函证汇总底稿。
B27: 3、请对大额存单是否属于“现金等价物”作出判断：
B30: 编制说明：
B31: 1、本表格主要可用于检查被审计单位账面金额、是否被质押或限制使用，存单是否为被审计单位所拥有程序。
B32: 2、由于活期存款一般金额较小，此表测算的定期存款利息收入也用于检查存款利息收入的整体合理性。

Sheet 1010-10
A1: << | B1: 货币资金受限情况明细表 | H1: 索引号： | I1: =目录!E16 -> 1010-10
B2: =目录!G4&目录!J4&" "&目录!G5&目录!H5&" "&目录!G6&目录!H6&" "&目录!I5&目录!J5&目录!L5&" "&目录!I6&目录!J6&目录!L6 -> 被审计单位：钢力金属 会计期间：2024-1-1至2024-12-31 截止日期：2024-12-31 编制人：黄振通2025-1-23 复核人：王裕昆2025-2-10
AK3: 不设打印区域：
B4: 受限资金种类 | C4: 所属单位 | D4: 币种 | E4: 原币 | F4: 汇率 | G4: 本位币金额 | H4: 受限原因 | I4: 备注 | AK4: 项目 | AL4: 期初审定数 | AM4: 期末审定数
B5: 银行承兑汇票保证金 | G5: =E5*F5 -> 0 | AK5: =B5&"" -> 银行承兑汇票保证金 | AM5: =SUMIF($B$5:$B$11,AK5,$G$5:$G$11) -> 0
B6: 信用证保证金 | G6: =E6*F6 -> 0 | AK6: =B6&"" -> 信用证保证金 | AM6: =SUMIF($B$5:$B$11,AK6,$G$5:$G$11) -> 0
B7: 履约保证金 | G7: =E7*F7 -> 0 | AK7: =B7&"" -> 履约保证金 | AM7: =SUMIF($B$5:$B$11,AK7,$G$5:$G$11) -> 0
B8: 用于担保的定期存款或通知存款 | G8: =E8*F8 -> 0 | AK8: =B8&"" -> 用于担保的定期存款或通知存款 | AM8: =SUMIF($B$5:$B$11,AK8,$G$5:$G$11) -> 0
B9: 放在境外且资金汇回受到限制的款项 | G9: =E9*F9 -> 0 | AK9: =B9&"" -> 放在境外且资金汇回受到限制的款项 | AM9: =SUMIF($B$5:$B$11,AK9,$G$5:$G$11) -> 0
G10: =E10*F10 -> 0 | AK10: =B10&"" | AM10: =SUMIF($B$5:$B$11,AK10,$G$5:$G$11) -> 0
G11: =E11*F11 -> 0 | AK11: =B11&"" | AM11: =SUMIF($B$5:$B$11,AK11,$G$5:$G$11) -> 0
A12: 技术支持和风控部：请保留此行为空白行且勿删除
B13: 合 计 | E13: =SUM(E5:E11) -> 0 | G13: =SUM(G5:G11) -> 0 | AK13: 合计 | AL13: =SUM(AL5:AL11) -> 0 | AM13: =SUM(AM5:AM11) -> 0
B15: 审计说明：
B20: 编制说明：
B21: 1、本表格主要可用于使用受限的保证金对现金流量表影响的审计程序。
B22: 2、受限资金主要包括定期存款、保证金等。

Sheet 1010-11
A1: << | B1: 货币资金外币折算表 | I1: 索引号： | J1: =目录!E17 -> 1010-11
B2: =目录!G4&目录!J4&" "&目录!G5&目录!H5&" "&目录!G6&目录!H6&" "&目录!I5&目录!J5&目录!L5&" "&目录!I6&目录!J6&目录!L6 -> 被审计单位：钢力金属 会计期间：2024-1-1至2024-12-31 截止日期：2024-12-31 编制人：黄振通2025-1-23 复核人：王裕昆2025-2-10
B4: 项目 | C4: 账号 | D4: 币种 | E4: 账面本位币余额 | F4: 外币余额 | G4: 折算汇率 | H4: 测算本位币余额 | I4: 差异 | J4: 备注
B5: 库存现金 | H5: =SUM(H6:H8) -> 0 | I5: =SUM(I6:I8) -> 0
H6: =ROUND(F6*G6,2) -> 0 | I6: =E6-H6 -> 0
H7: =ROUND(F7*G7,2) -> 0 | I7: =E7-H7 -> 0
H8: =ROUND(F8*G8,2) -> 0 | I8: =E8-H8 -> 0
B9: 银行存款 | H9: =SUM(H10:H14) -> 0 | I9: =SUM(I10:I14) -> 0
H10: =ROUND(F10*G10,2) -> 0 | I10: =E10-H10 -> 0
H11: =ROUND(F11*G11,2) -> 0 | I11: =E11-H11 -> 0
H12: =ROUND(F12*G12,2) -> 0 | I12: =E12-H12 -> 0
H13: =ROUND(F13*G13,2) -> 0 | I13: =E13-H13 -> 0
H14: =ROUND(F14*G14,2) -> 0 | I14: =E14-H14 -> 0
B15: 其他货币资金 | H15: =SUM(H16:H20) -> 0 | I15: =SUM(I16:I20) -> 0
H16: =ROUND(F16*G16,2) -> 0 | I16: =E16-H16 -> 0
H17: =ROUND(F17*G17,2) -> 0 | I17: =E17-H17 -> 0
H18: =ROUND(F18*G18,2) -> 0 | I18: =E18-H18 -> 0
H19: =ROUND(F19*G19,2) -> 0 | I19: =E19-H19 -> 0
H20: =ROUND(F20*G20,2) -> 0 | I20: =E20-H20 -> 0
B21: 合计 | H21: =H15+H9+H5 -> 0 | I21: =I15+I9+I5 -> 0
B24: 审计说明：
B29: 编制说明：
B30: 本表格主要可用于检查非记账本位币库存现金、银行存款、其他货币资金的折算汇率及折算金额是否正确程序：

Sheet 1010-12
A1: << | B1: 银行存款账面收付记录与银行对账单抽样核对表 | N1: 索引号： | O1: =目录!E18 -> 1010-12
B2: =目录!G4&目录!J4&" "&目录!G5&目录!H5&" "&目录!G6&目录!H6&" "&目录!I5&目录!J5&目录!L5&" "&目录!I6&目录!J6&目录!L6 -> 被审计单位：钢力金属 会计期间：2024-1-1至2024-12-31 截止日期：2024-12-31 编制人：黄振通2025-1-23 复核人：王裕昆2025-2-10
B4: 1、由日记账查询至对账单
B5: 序号 | C5: 所属单位 | D5: 开户行 | E5: 账号 | F5: 记账日期 | G5: 凭证号 | H5: 摘要 | I5: 银行存款日记账金额 | J5: 银行对账单日期 | K5: 交易对手 | L5: 银行对账单金额 | M5: 差额 | N5: 对账单索引 | O5: 备注
B6: 收款记录与银行对账单核对
B7: 1 | C7: 钢力金属 | D7: 建行广州大德路支行3210 | E7: 44001420301053013210 | F7: 2024-01-09 | G7: 2024-01记-0003 | H7: 收到2022年12月8号钢力总厂（2022）粤01强清125号强制清算费用退款 | I7: 52966.74 | J7: 2024-01-09 | K7: 广州金属制品供应贸公司清算组 | L7: 52966.74 | M7: =I7-L7 -> 0
B8: 2 | C8: 钢力金属 | D8: 建行广州大德路支行3210 | E8: 44001420301053013210 | F8: 2024-01-11 | G8: 2024-01记-0004 | H8: 收到建设银行下拨款 | I8: 330000 | J8: 2024-01-11 | K8: 广州工业投资控股有限公司 | L8: 330000 | M8: =I8-L8 -> 0
B9: 3 | C9: 钢力金属 | D9: 建行广州大德路支行3210 | E9: 44001420301053013210 | F9: 2024-09-11 | G9: 2024-09记-0001 | H9: 收松岗分厂往来款 | I9: 124000 | J9: 45547 | K9: 广州钢力金属制品总厂有限公司松岗分厂 | L9: 124000 | M9: =I9-L9 -> 0
B10: 4 | C10: 钢力金属 | D10: 建行广州大德路支行3210 | E10: 44001420301053013210 | F10: 2024-10-10 | G10: 2024-10记-0005 | H10: 收到建设银行下拨款 | I10: 200000 | J10: 2024-10-10 | K10: 广州工业投资控股集团有限公司 | L10: 200000 | M10: =I10-L10 -> 0
B11: 5 | C11: 钢力金属 | D11: 建行广州大德路支行3210 | E11: 44001420301053013210 | F11: 2024-10-14 | G11: 2024-10记-0006 | H11: 收工控资产2023年租金 | I11: 2100000 | J11: 2024-10-14 | K11: 广州工业投资控股集团有限公司 | L11: 2100000 | M11: =I11-L11 -> 0
B12: 6 | M12: =I12-L12 -> 0
B13: 7 | M13: =I13-L13 -> 0
B14: 8 | M14: =I14-L14 -> 0
B15: 9 | M15: =I15-L15 -> 0
B16: 10 | M16: =I16-L16 -> 0
M17: =I17-L17 -> 0
B18: 付款记录与银行对账单核对
B19: 1 | C19: 钢力金属 | D19: 建行广州大德路支行3210 | E19: 44001420301053013210 | F19: 2024-01-15 | G19: 2024-01记-0009 | H19: 支付松岗分厂往来款 | I19: 90000 | J19: 2024-01-15 | K19: 广州钢力金属制品总厂有限公司松岗分厂 | L19: 90000 | M19: =I19-L19 -> 0
B20: 2 | C20: 钢力金属 | D20: 建行广州大德路支行3210 | E20: 44001420301053013210 | F20: 2024-04-11 | G20: 2024-04记-0004 | H20: 支付松岗分厂往来款 | I20: 30000 | J20: 2024-04-11 | K20: 广州钢力金属制品总厂有限公司松岗分厂 | L20: 30000 | M20: =I20-L20 -> 0
B21: 3 | C21: 钢力金属 | D21: 建行广州大德路支行3210 | E21: 44001420301053013210 | F21: 2024-04-11 | G21: 2024-04记-0006 | H21: 缴纳2024年第一季度从租计征房产税 | I21: 30000 | J21: 2024-04-11 | K21: 待报解预算收入（财库联网集中户） | L21: 30000 | M21: =I21-L21 -> 0
B22: 4 | C22: 钢力金属 | D22: 建行广州大德路支行3210 | E22: 44001420301053013210 | F22: 2024-07-12 | G22: 2024-07记-0004 | H22: 支付松岗分厂往来款 | I22: 40000 | J22: 2024-07-12 | K22: 广州钢力金属制品总厂有限公司松岗分厂 | L22: 40000 | M22: =I22-L22 -> 0
B23: 5 | C23: 钢力金属 | D23: 建行广州大德路支行3210 | E23: 44001420301053013210 | F23: 2024-10-15 | G23: 2024-10记-0008 | H23: 缴纳2024年第三季度增值税及附加税 | I23: 37857.14 | J23: 2024-10-15 | K23: 待报解预算收入（财库联网集中户） | L23: 37857.14 | M23: =I23-L23 -> 0
B24: 6 | M24: =I24-L24 -> 0
B25: 7 | M25: =I25-L25 -> 0
B26: 8 | M26: =I26-L26 -> 0
B27: 9 | M27: =I27-L27 -> 0
B28: 10 | M28: =I28-L28 -> 0
M29: =I29-L29 -> 0
B31: 2、由对账单查询至日记账
B32: 序号 | D32: 开户行 | E32: 账号 | F32: 记账日期 | G32: 凭证号 | H32: 摘要 | I32: 银行存款日记账金额 | J32: 银行对账单日期 | K32: 交易对手 | L32: 银行对账单金额 | M32: 差额 | N32: 对账单索引 | O32: 备注
B33: 收款记录与银行对账单核对
B34: 1 | C34: 钢力金属 | D34: 建行广州大德路支行3210 | E34: 44001420301053013210 | F34: 45393 | G34: 2024-04记-0003 | H34: 收到建设银行下拨款 | I34: 100000 | J34: 45392 | K34: 广州工业投资控股有限公司 | L34: 100000 | M34: =I34-L34 -> 0
B35: 2 | C35: 钢力金属 | D35: 建行广州大德路支行3210 | E35: 44001420301053013210 | F35: 2024-07-12 | G35: 2024-07记-0002 | H35: 收到建设银行下拨款 | I35: 100000 | J35: 45488 | K35: 广州工业投资控股有限公司 | L35: 100000 | M35: =I35-L35 -> 0
B36: 3 | C36: 钢力金属 | D36: 建行广州大德路支行3210 | E36: 44001420301053013210 | F36: 2024-09-12 | G36: 2024-09记-0003 | H36: 付离休老干遗孀冯焕好2024年第3季度生活补贴 | I36: 5943 | J36: 2024-09-12 | K36: 冯焕好 | L36: 5943 | M36: =I36-L36 -> 0
B37: 4 | C37: 钢力金属 | D37: 建行广州大德路支行3210 | E37: 44001420301053013210 | F37: 2024-09-11 | G37: 2024-09记-0001 | H37: 收松岗分厂往来款 | I37: 124000 | J37: 45547 | K37: 广州钢力金属制品总厂有限公司松岗分厂 | L37: 124000 | M37: =I37-L37 -> 0
B38: 5 | C38: 钢力金属 | D38: 建行广州大德路支行3210 | E38: 44001420301053013210 | F38: 2024-10-18 | G38: 2024-10记-0016 | H38: 建行归集款 | I38: 2100000 | J38: 2024-10-18 | K38: 广州工业投资控股集团有限公司 | L38: 2100000 | M38: =I38-L38 -> 0
B39: 6 | M39: =I39-L39 -> 0
B40: 7 | M40: =I40-L40 -> 0
B41: 8 | M41: =I41-L41 -> 0
B42: 9 | M42: =I42-L42 -> 0
...

Sheet 1010-13
A1: << | B1: 货币资金凭证抽查表 | M1: 索引号： | N1: =目录!E19 -> 1010-13
B2: =目录!G4&目录!J4&" "&目录!G5&目录!H5&" "&目录!G6&目录!H6&" "&目录!I5&目录!J5&目录!L5&" "&目录!I6&目录!J6&目录!L6 -> 被审计单位：钢力金属 会计期间：2024-1-1至2024-12-31 截止日期：2024-12-31 编制人：黄振通2025-1-23 复核人：王裕昆2025-2-10
B4: 所属单位 | C4: 记账日期 | D4: 凭证编号 | E4: 业务内容 | F4: 会计科目 | G4: 借方金额 | H4: 贷方金额 | I4: 核对内容 （用“√”、“×”表示） | N4: 附件
I5: 1 | J5: 2 | K5: 3 | L5: 4 | M5: 5
B6: 广州钢力金属制品总厂有限公司 | C6: 2024-04-12 | D6: 2024-04记-0008 | E6: 收到建设银行下拨款 | F6: 银行存款\建设银行 | G6: 2600000 | I6: √ | J6: √ | K6: √ | L6: √
B7: 广州钢力金属制品总厂有限公司 | C7: 2024-08-27 | D7: 2024-08记-0007 | E7: 建行归集款 | F7: 银行存款\建设银行 | H7: 800000 | I7: √ | J7: √ | K7: √ | L7: √
B8: 广州钢力金属制品总厂有限公司 | C8: 2024-09-11 | D8: 2024-09记-0002 | E8: 收离休老干遗孀冯焕好2024年第3季度生活补贴 | F8: 银行存款\工商银行 | G8: 5943 | I8: √ | J8: √ | K8: √ | L8: √
B9: 广州钢力金属制品总厂有限公司 | C9: 2024-10-14 | D9: 2024-10记-0006 | E9: 收工控资产2023年租金 | F9: 银行存款\建设银行 | G9: 2100000 | I9: √ | J9: √ | K9: √ | L9: √
B10: 广州钢力金属制品总厂有限公司 | C10: 2024-10-18 | D10: 2024-10记-0016 | E10: 建行归集款 | F10: 银行存款\建设银行 | H10: 2100000 | I10: √ | J10: √ | K10: √ | L10: √
B15: 核对内容说明：
B16: 收入检查：1、银行收款凭证与银行对账单核对相符；2、收款凭证与销售发票、收据核对相符；3、收款凭证的对应科目与付款单位的户名一致；4、收款凭证账务处理正确；5、收款凭证与对应科目(销售或应收账款)明细账的记录一致，所收款项与经营活动相关。……
B17: 支出检查：1、付款的授权审批手续齐全、签章完整；2、原始凭证具有合法的发票或依据；3、原始凭证的内容和金额与付款凭证摘要核对一致；4、付款凭证与银行对账单核对相符；5、付款凭证与对应科目（如应付账款）明细账的记录一致，付款凭证账务处理正确。……
B18: 注：当企业规模和业务量较大时，可分库存现金、银行存款、其他货币资金科目分别使用该表，应注意修改索引号。
B19: 审计说明：
B20: 经抽查凭证，原始凭证齐全、与记账凭证相符、账务处理正确、记录于恰当的会计期间。

Sheet 1010-14
A1: << | B1: 大额现金交易合理性检查程序表 | J1: 索引号： | K1: =目录!E20 -> 1010-14
B2: =目录!G4&目录!J4&" "&目录!G5&目录!H5&" "&目录!G6&目录!H6&" "&目录!I5&目录!J5&目录!L5&" "&目录!I6&目录!J6&目录!L6 -> 被审计单位：钢力金属 会计期间：2024-1-1至2024-12-31 截止日期：2024-12-31 编制人：黄振通2025-1-23 复核人：王裕昆2025-2-10
B4: 序号 | C4: 项目
B5: 1
B6: 2
B7: 3
B8: 4
B9: 5
B11: 审计说明：

Sheet 1011
A1: <<
B2: 转至货币资金函证程序工作底稿

Sheet TB
A1: 报表项目
A2: 一级科目 | B2: 二级科目 | C2: 三级科目
A3: 库存现金 | B3: 存货——原材料 | C3: 应付福利费——#职工奖励及福利基金
A4: 银行存款 | B4: 存货——库存商品（产成品）
A5: 其他货币资金 | B5: 其他非流动资产——特准储备物资
A6: 结算备付金 | B6: 应付职工薪酬——应付工资
A7: 拆出资金 | B7: 应付职工薪酬——应付福利费
A8: 交易性金融资产 | B8: 应交税费——应交税金
A9: 衍生金融资产 | B9: 应付债券——优先股
A10: 应收票据 | B10: 应付债券——永续债
A11: 应收票据坏账准备 | B11: 其他非流动负债——特准储备基金
A12: 应收账款 | B12: 其他权益工具——优先股
A13: 应收账款坏账准备 | B13: 其他权益工具——永续债
A14: 应收款项融资 | B14: 其他综合收益——外币报表折算差额
A15: 应收款项融资坏账准备 | B15: 财务费用——利息费用
... A20: 应收分保合同准备金 | B20: 营业外收入——政府补助
A21: 应收资金集中管理款
A22: 应收利息
A23: 应收利息坏账准备
A24: 应收股利
A25: 应收股利坏账准备
A26: 其他应收款
A27: 其他应收款坏账准备
A28: 买入返售金融资产
A29: 存货
A30: 存货跌价准备
A31: 合同资产
A32: 合同资产减值准备
... A170: 少数股东损益

Sheet ZZX-Template
B1: XX | J1: 索引号: | K1: XXXX-x
B2: xxx
B4: 序号 | C4: 项目
B5: 1
B6: 2
B7: 3
B8: 4
B9: 5
B11: 审计说明：
