Workbook
Name Print_Area_MI: #REF!
Name 二级科目: TB!$B$3:$B$20
Name 科目表: [2]TB!$A$3:[2]TB!$A$170
Name 科目表: TB!$A$3:$A$170
Name 科目设置: TB!$A$3:$A$170
Name 三级科目: TB!$C$3:$C$3

Sheet 目录
B2: 管理费用审计工作底稿 | G2: 所属会计师事务所： 广东中职信会计师事务所（特殊普通合伙）
B3: 工作表名 | C3: 工作底稿名称 | D3: 是否需要编制 | E3: 索引号 | G3: 被审计单位： | H3: 广州钢力金属制品总厂有限公司 | I3: 被审单位简称： | J3: 钢力金属 | K3: 货币单位： | L3: 人民币/元
B4: 4110 | C4: 管理费用程序表 | D4: 是 | E4: 4110 | G4: 会计期间： | H4: 2024-1-1至2024-12-31 | I4: 编制人： | J4: 黄振通 | K4: 日期： | L4: 2025-1-21
B5: 4110-1 | C5: 管理费用审计调整分录 | D5: 是 | E5: 4110-1 | G5: 截止日期： | H5: 2024-12-31 | I5: 复核人： | J5: 王裕昆 | K5: 日期： | L5: 2025-2-10
B6: 4110-2 | C6: 管理费用审定表 | D6: 是 | E6: 4110-2
B7: 4110-3 | C7: 管理费用明细表 | D7: 是 | E7: 4110-3
B8: 4110-4 | C8: 管理费用两期对比表 | D8: 是 | E8: 4110-4
B9: 4110-5 | C9: 大额管理费用合同检查表 | D9: 是 | E9: 4110-5
B10: 4110-6 | C10: 管理费用截止性测试 | D10: 是 | E10: 4110-6
B11: 4110-7 | C11: 管理费用凭证抽查表 | D11: 是 | E11: 4110-7

Sheet 4110
A1: << | B1: 管理费用实质性程序 | K1: 索引号： | L1: =目录!E4 -> 4110
B2: =目录!G3&目录!J3&" "&目录!G4&目录!H4&" "&目录!G5&目录!H5&" "&目录!I4&目录!J4&""&目录!L4&" "&目录!I5&目录!J5&""&目录!L5 -> 被审计单位：钢力金属 会计期间：2024-1-1至2024-12-31 截止日期：2024-12-31 编制人：黄振通2025-1-21 复核人：王裕昆2025-2-10
B4: 审计目标 | G4: 财务报表认定
G5: 发生 | H5: 完整性 | I5: 准确性 | J5: 截止 | K5: 分类和列报
B6: A | D6: 利润表中记录的管理费用已发生，且与被审计单位有关。 | G6: √
B7: B | D7: 所有应当记录的管理费用均已记录。 | H7: √
B8: C | D8: 与管理费用有关的金额及其他数据已恰当记录。 | I8: √
B9: D | D9: 管理费用已记录于正确的会计期间。 | J9: √
B10: E | D10: 管理费用已记录于恰当的账户、已按照企业会计准则的规定在财务报表中作出恰当的列报。 | K10: √
B11: 计划实施的实质性程序
B12: 审计目标 | C12: 序号 | D12: 实质性程序 | E12: 是否执行 | F12: 索引号 | G12: 发生 | H12: 完整性 | I12: 准确性 | J12: 截止 | K12: 分类和列报
B13: C | C13: 1 | D13: 获取或编制管理费用明细表： （1）复核加计是否正确，并与报表数、总账数及明细账合计数核对是否相符； （2）将管理费用中的职工薪酬、无形资产摊销、长期待摊费用摊销额等项目与各有关账户进行核对，分析其勾稽关系的合理性，并作出相应记录。 | E13: 是 | F13: =目录!E7 -> 4110-3 | I13: √
B14: ABC | C14: 2 | D14: 对管理费用进行分析： (1)计算分析管理费用中各项目发生额及占费用总额的比率，将本期、上期管理费用各主要明细项目作比较分析，判断其变动的合理性； (2)将管理费用实际金额与预算金额进行比较； (3)比较本期各月份管理费用，对有重大波动和异常情况的项目应查明原因，必要时作适当处理。 | E14: 是 | F14: =目录!E8 -> 4110-4 | G14: √ | H14: √ | I14: √
B15: E | C15: 3 | D15: 检查管理费用的明细项目的设置是否符合规定的核算内容与范围，结合成本费用的审计，检查是否存在费用分类错误，若有，应提请被审计单位调整 | E15: 是 | F15: =目录!E7 -> 4110-3 | K15: √
B16: ABC | C16: 4 | D16: 检查公司经费(包括行政管理部门职工薪酬、物料消耗、低值易耗品摊销、办公费和差旅费)是否系经营管理中发生或应由公司统一负担，检查相关费用报销内部管理办法，是否有合法原始凭证支持。 | E16: 是 | F16: =目录!E11 -> 4110-7 | G16: √ | H16: √ | I16: √
B17: ABC | C17: 5 | D17: 检查董事会费（包括董事会成员津贴、会议费和差旅费等），检查相关董事会及股东会决议，是否在合规范围内开支费用。 | E17: 是 | F17: =目录!E11 -> 4110-7 | G17: √ | H17: √ | I17: √
B18: ABC | C18: 6 | D18: 检查聘请中介机构费、咨询费（含顾问费），检查是否按合同规定支付费用，有无涉及到诉讼及赔偿款项支出。 | E18: 是 | F18: =目录!E11 -> 4110-7 | G18: √ | H18: √ | I18: √
B19: ABC | C19: 7 | D19: 检查诉讼费用并结合或有事项审计,检查涉及的相关重大诉讼事项是否已在附注中进行披露，还需进一步关注诉讼状态，判断有无或有负债，或是否存在损失已发生而未入账的事项。 | E19: 是 | F19: =目录!E11 -> 4110-7 | G19: √ | H19: √ | I19: √
B20: C | C20: 8 | D20: 检查业务招待费的支出是否合理，如超过规定限额，应在计算应纳税所得额时调整。 | E20: 是 | F20: =目录!E11 -> 4110-7 | I20: √
B21: C | C21: 9 | D21: 重新计算或检查本期发生的矿产资源补偿费、房产税、土地使用税、印花税等税费，确定其计算是否正确。 | E21: 是 | F21: 2160-10 | I21: √
B22: ABC | C22: 10 | D22: 结合相关资产的检查，核对筹建期间发生的开办费（包括人员工资、办公费、培训费、差旅费、印刷费、注册登记费以及不计入固定资产成本的借款费用等）是否直接计入管理费用。 | E22: 是 | F22: =目录!E11 -> 4110-7 | G22: √ | H22: √ | I22: √
B23: ABC | C23: 11 | D23: 针对特殊行业，检查排污费等环保费用是否合理计提。 | E23: 是 | F23: =目录!E11 -> 4110-7 | G23: √ | H23: √ | I23: √
B24: ABC | C24: 12 | D24: 选择重要或异常的管理费用，检查费用的开支标准是否符合有关规定，计算是否正确，原始凭证是否合法，会计处理是否正确。 | E24: 是 | F24: =目录!E9 -> 4110-5 | G24: √ | H24: √ | I24: √
B25: BD | C25: 13 | D25: 实施截止性测试，若存在异常迹象，考虑是否有必要追加审计程序，对于重大跨期项目，应作必要调整。 抽取资产负债表日前后天的XX张凭证，实施截止测试，若存在异常迹象，应考虑是否有必要追加审计程序。从资产负债表日后的银行对账单或付款凭证中选取项目进行测试，检查支持性文件（如合同或发票），关注发票日期和支付日期，追踪已选取项目至相关费用明细表，检查费用是否被记录于正确的会计期间。 | E25: 是 | F25: =目录!E10 -> 4110-6 | H25: √ | J25: √
C26: 14 | D26: 根据评估的舞弊风险等因素增加的其他审计程序。
B27: E | C27: 15 | D27: 确定管理费用是否已按照企业会计准则的规定在财务报表中作出恰当的列报。 | E27: 是 | K27: √

Sheet 4110-1
A1: << | B1: 管理费用审计调整分录 | I1: 索引号： | J1: =目录!E5 -> 4110-1
B2: =目录!G3&目录!J3&" "&目录!G4&目录!H4&" "&目录!G5&目录!H5&" "&目录!I4&目录!J4&""&目录!L4&" "&目录!I5&目录!J5&""&目录!L5 -> 被审计单位：钢力金属 会计期间：2024-1-1至2024-12-31 截止日期：2024-12-31 编制人：黄振通2025-1-21 复核人：王裕昆2025-2-10
B4: 分录序号 | C4: 调整事项说明 | D4: 报表科目 | E4: 二级科目 | F4: 三级科目 | G4: 明细项目 | H4: 调 整 金 额 | J4: 备注
H5: 借 方 | I5: 贷 方
B6: [START] | D6: =IF(ROUND((H6-I6),2)<>0,"调整分录不平",ROUND((H6-I6),2)) -> 0 | H6: =SUM(H7:H50) -> 0 | I6: =SUM(I7:I50) -> 0
Y8: G | AC8: G

Sheet 4110-2
A1: << | B1: 管理费用审定表 | G1: 索引号： | H1: =目录!E6 -> 4110-2
B2: =目录!G3&目录!J3&" "&目录!G4&目录!H4&" "&目录!G5&目录!H5&" "&目录!I4&目录!J4&""&目录!L4&" "&目录!I5&目录!J5&""&目录!L5 -> 被审计单位：钢力金属 会计期间：2024-1-1至2024-12-31 截止日期：2024-12-31 编制人：黄振通2025-1-21 复核人：王裕昆2025-2-10
B4: 项 目 | C4: 本期未审数 | D4: 审计调整 | E4: 本期审定数 | F4: 上期审定数 | G4: 对比上期变动额 | H4: 变动率
B5: 管理费用 | C5: ='4110-3'!R5 -> 1904775.2 | D5: =SUMIF('4110-1'!D7:D50,B5,'4110-1'!H7:H50)-SUMIF('4110-1'!D7:D50,B5,'4110-1'!I7:I50) -> 0 | E5: =C5+D5 -> 1904775.2 | F5: ='4110-3'!M134 -> 2095612.7 | G5: =E5-F5 -> -190837.44 | H5: =IFERROR(IF(F5<0,"不适用",G5/F5),"") -> -0.091065226
D6: =D5-'4110-3'!S5 -> 0 | E6: =E5-'4110-3'!T5 -> 0
B7: 审计说明:
B8: 1、对审定数的分析性复核（即本期数与上期数的变动分析）：具体原因：
B9: 2、已对管理费用有关明细发生额与相应的计提科目的贷方发生额存在勾稽关系的款项进行配比性的核对与交叉复核，详见“4110-3”
B10: 3、已编制管理费用明细表，账账、账表核对一致，详见“4110-3”、“4110-4”；
B11: 4、已取得租赁费、物业费等项目相关的合同等资料，并与被审计单位账面记录进行核对，对于与账面金额存在重大差异的调查分析，详见“4110-5”；
B12: 5、抽取资产负债表日前后大额发生额的凭证，实施截止测试，确认不存在重大的跨期支出情况，详见“4110-6”；
B13: 6、对本期发生的管理费用，选取样本（需说明选取样本的原则或者选取样本的计算过程做相关索引），检查其支持性文件，详见“4110-7”；
B16: 审计调整： | C16: 无
B20: 审计结论: | C20: 经审计调整后，发生额可以确认。
C24: 无
C25: 参见4110-1
C29: 经审计调整后，余额可以确认。
C30: 经审计后，无调整事项，余额可以确认。
C31: 经审计调整后，发生额可以确认。
C32: 经审计后，无调整事项，发生额可以确认。
C33: 经审计测试后，未见异常。
C34: 经我们审计，除上述说明事项外，未发现其他重大异常。
C35: [自定义审计结论1…]
C36: [自定义审计结论2…]
C37: [自定义审计结论3…]

Sheet 4110-3
A1: << | B1: 管理费用明细表 | U1: 索引号： | V1: =目录!E7 -> 4110-3
B2: =目录!G3&目录!J3&" "&目录!G4&目录!H4&" "&目录!G5&目录!H5&" "&目录!I4&目录!J4&""&目录!L4&" "&目录!I5&目录!J5&""&目录!L5 -> 被审计单位：钢力金属 会计期间：2024-1-1至2024-12-31 截止日期：2024-12-31 编制人：黄振通2025-1-21 复核人：王裕昆2025-2-10
B4: 序号 | C4: 所属单位 | D4: 项目 | E4: 披露项目 | F4: 1月 | G4: 2月 | H4: 3月 | I4: 4月 | J4: 5月 | K4: 6月 | L4: 7月 | M4: 8月 | N4: 9月 | O4: 10月 | P4: 11月 | Q4: 12月 | R4: 本期合计 | S4: 调整数 | T4: 审定数 | U4: 比例 | V4: 备注
B5: 合计数 | F5: =SUM(F6:F118) -> 142819.16 | G5: =SUM(G6:G118) -> 139284.91 | H5: =SUM(H6:H118) -> 278436.06 | I5: =SUM(I6:I118) -> 50.89 | J5: =SUM(J6:J118) -> 146032.19 | K5: =SUM(K6:K118) -> 278520.09 | L5: =SUM(L6:L118) -> 150191.22 | M5: =SUM(M6:M118) -> 15.81 | ... U5: =SUM(U6:U118) -> 1
B6: 1 | C6: 钢力金属 | D6: 其他管理费用 | E6: =IFERROR(VLOOKUP(D6,$E$133:$F$166,2,0),"") -> 保险费 | Q6: 6270.42 | R6: =SUM(F6:Q6) -> 6270.42 | T6: =R6+S6 -> 6270.42 | U6: =IF(T6=0,"",T6/$T$5) -> 0.0032919475
B7: 2 | C7: 钢力金属 | D7: 其他专项费用 | E7: =IFERROR(VLOOKUP(D7,$E$133:$F$166,2,0),"") -> 其他 | F7: 3796.2 | H7: 300 | J7: 2600 | K7: 600 | L7: 2000 | N7: 2994 | R7: =SUM(F7:Q7) -> 12290.2 | T7: =R7+S7 -> 12290.2 | U7: =IF(T7=0,"",T7/$T$5) -> 0.0064523099
B8: 3 | C8: 钢力金属 | D8: 电费 | E8: =IFERROR(VLOOKUP(D8,$E$133:$F$166,2,0),"") -> 其他 | F8: 90.76 | G8: 352.78 | H8: 271.66 | I8: 50.96 | K8: 55.76 | L8: 59.03 | M8: 15.89 | O8: 2537.47 | P8: 1055.69 | Q8: 17.36 | R8: =SUM(F8:Q8) -> 4507.36 | T8: =R8+S8 -> 4507.36 | U8: =IF(T8=0,"",T8/$T$5) -> 0.0023663475
B9: 4 | C9: 钢力金属 | D9: 无形资产摊销 | E9: =IFERROR(VLOOKUP(D9,$E$133:$F$166,2,0),"") -> 无形资产摊销 | Q9: 200821.29 | R9: =SUM(F9:Q9) -> 200821.29 | T9: =R9+S9 -> 200821.29 | U9: =IF(T9=0,"",T9/$T$5) -> 0.10543044
B10: 5 | C10: 钢力金属 | D10: 折旧费 | E10: =IFERROR(VLOOKUP(D10,$E$133:$F$166,2,0),"") -> 折旧费 | F10: 138932.2 | G10: 138932.13 | H10: 277864.4 | I10: -0.07 | J10: 138932.19 | K10: 277864.33 | L10: 138932.19 | M10: -0.08 | N10: 138932.2 | O10: 138932.13 | P10: 138932.2 | Q10: 138932.13 | R10: =SUM(F10:Q10) -> 1667185.9 | T10: =R10+S10 -> 1667185.9 | U10: =IF(T10=0,"",T10/$T$5) -> 0.87526651
B11: 6 | C11: 钢力金属 | D11: 评估费 | E11: =IFERROR(VLOOKUP(D11,$E$133:$F$166,2,0),"") -> 聘请中介机构费 | J11: 4500 | R11: =SUM(F11:Q11) -> 4500 | T11: =R11+S11 -> 4500 | U11: =IF(T11=0,"",T11/$T$5) -> 0.0023624835
B12: 7 | C12: 钢力金属 | D12: 审计费 | E12: =IFERROR(VLOOKUP(D12,$E$133:$F$166,2,0),"") -> 聘请中介机构费 | L12: 9200 | R12: =SUM(F12:Q12) -> 9200 | T12: =R12+S12 -> 9200 | U12: =IF(T12=0,"",T12/$T$5) -> 0.0048299662
B13: 8 | E13: =IFERROR(VLOOKUP(D13,$E$133:$F$166,2,0),"") | R13: =SUM(F13:Q13) -> 0 | T13: =R13+S13 -> 0 | U13: =IF(T13=0,"",T13/$T$5)
B14: 9 | E14: =IFERROR(VLOOKUP(D14,$E$133:$F$166,2,0),"") | R14: =SUM(F14:Q14) -> 0 | T14: =R14+S14 -> 0 | U14: =IF(T14=0,"",T14/$T$5)
B15: 10 | E15: =IFERROR(VLOOKUP(D15,$E$133:$F$166,2,0),"") | R15: =SUM(F15:Q15) -> 0 | T15: =R15+S15 -> 0 | U15: =IF(T15=0,"",T15/$T$5)
B16: 11 | E16: =IFERROR(VLOOKUP(D16,$E$133:$F$166,2,0),"") | R16: =SUM(F16:Q16) -> 0 | T16: =R16+S16 -> 0 | U16: =IF(T16=0,"",T16/$T$5)
B17: 12 | E17: =IFERROR(VLOOKUP(D17,$E$133:$F$166,2,0),"") | R17: =SUM(F17:Q17) -> 0 | T17: =R17+S17 -> 0 | U17: =IF(T17=0,"",T17/$T$5)
B18: 13 | E18: =IFERROR(VLOOKUP(D18,$E$133:$F$166,2,0),"") | R18: =SUM(F18:Q18) -> 0 | T18: =R18+S18 -> 0 | U18: =IF(T18=0,"",T18/$T$5)
B19: 14 | E19: =IFERROR(VLOOKUP(D19,$E$133:$F$166,2,0),"") | R19: =SUM(F19:Q19) -> 0 | T19: =R19+S19 -> 0 | U19: =IF(T19=0,"",T19/$T$5)
B20: 15 | E20: =IFERROR(VLOOKUP(D20,$E$133:$F$166,2,0),"") | R20: =SUM(F20:Q20) -> 0 | T20: =R20+S20 -> 0 | U20: =IF(T20=0,"",T20/$T$5)
B21: 16 | E21: =IFERROR(VLOOKUP(D21,$E$133:$F$166,2,0),"") | R21: =SUM(F21:Q21) -> 0 | T21: =R21+S21 -> 0 | U21: =IF(T21=0,"",T21/$T$5)
B22: 17 | E22: =IFERROR(VLOOKUP(D22,$E$133:$F$166,2,0),"") | R22: =SUM(F22:Q22) -> 0 | T22: =R22+S22 -> 0 | U22: =IF(T22=0,"",T22/$T$5)
B23: 18 | E23: =IFERROR(VLOOKUP(D23,$E$133:$F$166,2,0),"") | R23: =SUM(F23:Q23) -> 0 | T23: =R23+S23 -> 0 | U23: =IF(T23=0,"",T23/$T$5)
B24: 19 | E24: =IFERROR(VLOOKUP(D24,$E$133:$F$166,2,0),"") | R24: =SUM(F24:Q24) -> 0 | T24: =R24+S24 -> 0 | U24: =IF(T24=0,"",T24/$T$5)
... B118: 113 | E118: =IFERROR(VLOOKUP(D118,$E$133:$F$166,2,0),"") | R118: =SUM(F118:Q118) -> 0 | T118: =R118+S118 -> 0 | U118: =IF(T118=0,"",T118/$T$5)
B120: 审计说明：
B121: 1、经审计，明细表与审定数金额一致，项目分类与上年一致。
B122: 2、其他管理费用为支付钢力总厂2024年财产险保险年费。
B123: 3、其他专项费用为支付离休老干慰问金及资料费。
B128: 编制说明：
B129: 1.请在审计说明处说明职工薪酬、折旧、摊销等与资产类相关科目的勾稽性审核情况。
B130: 2.请在审计说明处结合月度变化，对某月发生的金额重大且存在畸高或畸低的情况进行分析说明。
E132: 企业账套项目与附注披露项目映射表： | I132: 不设打印区域：
B133: 附注披露项目罗列（自行修改项目） | E133: 企业账套项目 | F133: 附注披露项目-映射 | I133: 项目 | J133: 上期审计报告数 | K133: 重要会计政策变更影响额 | L133: 重要前期差错 | M133: 上期审定数
B134: 职工薪酬 | E134: 其他专项费用 | F134: 其他 | I134: 合计 | J134: =SUM(J135:J153) -> 2095612.7 | K134: =SUM(K135:K153) -> 0 | L134: =SUM(L135:L153) -> 0 | M134: =SUM(M135:M153) -> 2095612.7
B135: 保险费 | E135: 折旧费 | F135: 折旧费 | I135: =B134&"" -> 职工薪酬 | J135: 0 | M135: =J135+K135+L135 -> 0
B136: 折旧费 | E136: 中小修 | F136: 修理费 | I136: =B135&"" -> 保险费 | J136: 0 | M136: =J136+K136+L136 -> 0
B137: 修理费 | E137: 无形资产摊销 | F137: 无形资产摊销 | I137: =B136&"" -> 折旧费 | J137: 1673146.9 | M137: =J137+K137+L137 -> 1673146.9
B138: 无形资产摊销 | E138: 业务招待费 | F138: 业务招待费 | I138: =B137&"" -> 修理费 | J138: 0 | M138: =J138+K138+L138 -> 0
B139: 存货盘亏 | E139: 其他办公费 | F139: 办公费 | I139: =B138&"" -> 无形资产摊销 | J139: 200821.29 | M139: =J139+K139+L139 -> 200821.29
B140: 业务招待费 | E140: 办公室电话费 | F140: 办公费 | I140: =B139&"" -> 存货盘亏 | J140: 0 | M140: =J140+K140+L140 -> 0
...

Sheet 4110-4
A1: << | B1: 管理费用两期对比表 | J1: 索引号： | K1: =目录!E8 -> 4110-4
B2: =目录!G3&目录!J3&" "&目录!G4&目录!H4&" "&目录!G5&目录!H5&" "&目录!I4&目录!J4&""&目录!L4&" "&目录!I5&目录!J5&""&目录!L5 -> 被审计单位：钢力金属 会计期间：2024-1-1至2024-12-31 截止日期：2024-12-31 编制人：黄振通2025-1-21 复核人：王裕昆2025-2-10
B4: 序号 | C4: 项目 | D4: 上期 | F4: 本期 | H4: 变动 | K4: 异常变动原因说明
D5: 金额 | E5: 所占比例 | F5: 金额 | G5: 所占比例 | H5: 变动金额 | I5: 变动比例 | J5: 结构变动
D6: A | E6: B | F6: C | G6: D | H6: E=C-A | I6: F=E/A | J6: G=D-B
B7: 合计 | D7: =SUM(D8:D40) -> 2095612.7 | E7: =SUM(E8:E40) -> 1 | F7: =SUM(F8:F40) -> 1904775.2 | G7: =SUM(G8:G40) -> 1 | H7: =SUM(H8:H40) -> -190837.44 | I7: =IF(H7=0,0,H7/D7) -> -0.091065226 | J7: =G7-E7 -> 0
B8: 1 | C8: ='4110-3'!B134&"" -> 职工薪酬 | D8: =SUMIF('4110-3'!$I$135:$I$153,C8,'4110-3'!$M$135:$M$153) -> 0 | E8: =IF(D8=0,0,D8/$D$7) -> 0 | F8: =SUMIF('4110-3'!$E$6:$E$118,'4110-4'!C8,'4110-3'!$T$6:$T$118) -> 0 | G8: =IF(F8=0,0,F8/$F$7) -> 0 | H8: =F8-D8 -> 0 | I8: =IF(H8=0,0,H8/D8) -> 0 | J8: =G8-E8 -> 0
B9: 2 | C9: ='4110-3'!B135&"" -> 保险费 | D9: =SUMIF('4110-3'!$I$135:$I$153,C9,'4110-3'!$M$135:$M$153) -> 0 | E9: =IF(D9=0,0,D9/$D$7) -> 0 | F9: =SUMIF('4110-3'!$E$6:$E$118,'4110-4'!C9,'4110-3'!$T$6:$T$118) -> 6270.42 | G9: =IF(F9=0,0,F9/$F$7) -> 0.0032919475 | H9: =F9-D9 -> 6270.42 | I9: =IF(H9=0,0,H9/D9) -> #DIV/0! | J9: =G9-E9 -> 0.0032919475
B10: 3 | C10: ='4110-3'!B136&"" -> 折旧费 | D10: =SUMIF('4110-3'!$I$135:$I$153,C10,'4110-3'!$M$135:$M$153) -> 1673146.9 | E10: =IF(D10=0,0,D10/$D$7) -> 0.79840464 | F10: =SUMIF('4110-3'!$E$6:$E$118,'4110-4'!C10,'4110-3'!$T$6:$T$118) -> 1667185.9 | G10: =IF(F10=0,0,F10/$F$7) -> 0.87526651 | H10: =F10-D10 -> -5960.93 | I10: =IF(H10=0,0,H10/D10) -> -0.0035627057 | J10: =G10-E10 -> 0.076861861
B11: 4 | C11: ='4110-3'!B137&"" -> 修理费 | D11: =SUMIF('4110-3'!$I$135:$I$153,C11,'4110-3'!$M$135:$M$153) -> 0 | E11: =IF(D11=0,0,D11/$D$7) -> 0 | F11: =SUMIF('4110-3'!$E$6:$E$118,'4110-4'!C11,'4110-3'!$T$6:$T$118) -> 0 | G11: =IF(F11=0,0,F11/$F$7) -> 0 | H11: =F11-D11 -> 0 | I11: =IF(H11=0,0,H11/D11) -> 0 | J11: =G11-E11 -> 0
B12: 5 | C12: ='4110-3'!B138&"" -> 无形资产摊销 | D12: =SUMIF('4110-3'!$I$135:$I$153,C12,'4110-3'!$M$135:$M$153) -> 200821.29 | E12: =IF(D12=0,0,D12/$D$7) -> 0.095829393 | F12: =SUMIF('4110-3'!$E$6:$E$118,'4110-4'!C12,'4110-3'!$T$6:$T$118) -> 200821.29 | G12: =IF(F12=0,0,F12/$F$7) -> 0.10543044 | H12: =F12-D12 -> 0 | I12: =IF(H12=0,0,H12/D12) -> 0 | J12: =G12-E12 -> 0.0096010468
B13: 6 | C13: ='4110-3'!B139&"" -> 存货盘亏 | D13: =SUMIF('4110-3'!$I$135:$I$153,C13,'4110-3'!$M$135:$M$153) -> 0 | E13: =IF(D13=0,0,D13/$D$7) -> 0 | F13: =SUMIF('4110-3'!$E$6:$E$118,'4110-4'!C13,'4110-3'!$T$6:$T$118) -> 0 | G13: =IF(F13=0,0,F13/$F$7) -> 0 | H13: =F13-D13 -> 0 | I13: =IF(H13=0,0,H13/D13) -> 0 | J13: =G13-E13 -> 0
B14: 7 | C14: ='4110-3'!B140&"" -> 业务招待费 | D14: =SUMIF('4110-3'!$I$135:$I$153,C14,'4110-3'!$M$135:$M$153) -> 0 | E14: =IF(D14=0,0,D14/$D$7) -> 0 | F14: =SUMIF('4110-3'!$E$6:$E$118,'4110-4'!C14,'4110-3'!$T$6:$T$118) -> 0 | G14: =IF(F14=0,0,F14/$F$7) -> 0 | H14: =F14-D14 -> 0 | I14: =IF(H14=0,0,H14/D14) -> 0 | J14: =G14-E14 -> 0
B15: 8 | C15: ='4110-3'!B141&"" -> 差旅费 | D15: =SUMIF('4110-3'!$I$135:$I$153,C15,'4110-3'!$M$135:$M$153) -> 0 | E15: =IF(D15=0,0,D15/$D$7) -> 0 | F15: =SUMIF('4110-3'!$E$6:$E$118,'4110-4'!C15,'4110-3'!$T$6:$T$118) -> 0 | G15: =IF(F15=0,0,F15/$F$7) -> 0 | H15: =F15-D15 -> 0 | I15: =IF(H15=0,0,H15/D15) -> 0 | J15: =G15-E15 -> 0
B16: 9 | C16: ='4110-3'!B142&"" -> 办公费 | D16: =SUMIF('4110-3'!$I$135:$I$153,C16,'4110-3'!$M$135:$M$153) -> 280 | E16: =IF(D16=0,0,D16/$D$7) -> 0.00013361248 | F16: =SUMIF('4110-3'!$E$6:$E$118,'4110-4'!C16,'4110-3'!$T$6:$T$118) -> 0 | G16: =IF(F16=0,0,F16/$F$7) -> 0 | H16: =F16-D16 -> -280 | I16: =IF(H16=0,0,H16/D16) -> -1 | J16: =G16-E16 -> -0.00013361248
B17: 10 | C17: ='4110-3'!B143&"" -> 会议费 | D17: =SUMIF('4110-3'!$I$135:$I$153,C17,'4110-3'!$M$135:$M$153) -> 0 | E17: =IF(D17=0,0,D17/$D$7) -> 0 | F17: =SUMIF('4110-3'!$E$6:$E$118,'4110-4'!C17,'4110-3'!$T$6:$T$118) -> 0 | G17: =IF(F17=0,0,F17/$F$7) -> 0 | H17: =F17-D17 -> 0 | I17: =IF(H17=0,0,H17/D17) -> 0 | J17: =G17-E17 -> 0
B18: 11 | C18: ='4110-3'!B144&"" -> 诉讼费 | D18: =SUMIF('4110-3'!$I$135:$I$153,C18,'4110-3'!$M$135:$M$153) -> 0 | E18: =IF(D18=0,0,D18/$D$7) -> 0 | F18: =SUMIF('4110-3'!$E$6:$E$118,'4110-4'!C18,'4110-3'!$T$6:$T$118) -> 0 | G18: =IF(F18=0,0,F18/$F$7) -> 0 | H18: =F18-D18 -> 0 | I18: =IF(H18=0,0,H18/D18) -> 0 | J18: =G18-E18 -> 0
B19: 12 | C19: ='4110-3'!B145&"" -> 聘请中介机构费 | D19: =SUMIF('4110-3'!$I$135:$I$153,C19,'4110-3'!$M$135:$M$153) -> 24751.45 | E19: =IF(D19=0,0,D19/$D$7) -> 0.011811081 | F19: =SUMIF('4110-3'!$E$6:$E$118,'4110-4'!C19,'4110-3'!$T$6:$T$118) -> 13700 | G19: =IF(F19=0,0,F19/$F$7) -> 0.0071924497 | H19: =F19-D19 -> -11051.45 | I19: =IF(H19=0,0,H19/D19) -> -0.44649707 | J19: =G19-E19 -> -0.0046186309
... B40: 33 | C40: ='4110-3'!B166&"" | D40: =SUMIF('4110-3'!$I$135:$I$153,C40,'4110-3'!$M$135:$M$153) -> 0 | E40: =IF(D40=0,0,D40/$D$7) -> 0 | F40: =SUMIF('4110-3'!$E$6:$E$118,'4110-4'!C40,'4110-3'!$T$6:$T$118) -> 0 | G40: =IF(F40=0,0,F40/$F$7) -> 0 | H40: =F40-D40 -> 0 | I40: =IF(H40=0,0,H40/D40) -> 0 | J40: =G40-E40 -> 0
D41: ^ | F41: ^ | H41: ^
B42: 审计说明：
B43: 1、经审计，未发现重大异常情况，主要项目变动及原因如下。
B44: 2、“其他”项目变动较大，主要是由于2023支付钢力松岗松岗分厂细岗仔园区2022-2023年环境配套费180,000.00元，本期无该项支出。

Sheet 4110-5
A1: << | B1: 大额管理费用合同检查表 | L1: 索引号： | M1: =目录!E9 -> 4110-5
B2: =目录!G3&目录!J3&" "&目录!G4&目录!H4&" "&目录!G5&目录!H5&" "&目录!I4&目录!J4&""&目录!L4&" "&目录!I5&目录!J5&""&目录!L5 -> 被审计单位：钢力金属 会计期间：2024-1-1至2024-12-31 截止日期：2024-12-31 编制人：黄振通2025-1-21 复核人：王裕昆2025-2-10
B4: 项目 | C4: 对方单位 | D4: 合同/协议内容 | E4: 合同/协议金额 | F4: 合同/协议开始日期 | G4: 合同/协议结束日期 | H4: 合同总月份 | I4: 本期应计损益 | J4: 本期已计损益 | K4: 差异 | L4: 合同索引 | M4: 备注
K5: =I5-J5 -> 0
K6: =I6-J6 -> 0
K7: =I7-J7 -> 0
K8: =I8-J8 -> 0
K9: =I9-J9 -> 0
K10: =I10-J10 -> 0
K11: =I11-J11 -> 0
K12: =I12-J12 -> 0
K13: =I13-J13 -> 0
K14: =I14-J14 -> 0
K15: =I15-J15 -> 0
B16: 合计 | E16: =SUM(E5:E15) -> 0 | I16: =SUM(I5:I15) -> 0 | J16: =SUM(J5:J15) -> 0 | K16: =SUM(K5:K15) -> 0
B18: 合同检查内容：
B19: 1、取得租赁费、物业费、运输费、修理费、装修费、保险费、咨询费等项目相关的合同等资料。
B20: 2、将相关资料与被审计单位账面记录进行核对；
B21: 3、选择重要或异常的销售费用进行测算，对于与账面金额的重大差异进行调查；
B22: 审计说明：

Sheet 4110-6
A1: << | B1: 管理费用截止性测试 | G1: 索引号： | H1: =目录!E10 -> 4110-6
B2: =目录!G3&目录!J3&" "&目录!G4&目录!H4&" "&目录!G5&目录!H5&" "&目录!I4&目录!J4&""&目录!L4&" "&目录!I5&目录!J5&""&目录!L5 -> 被审计单位：钢力金属 会计期间：2024-1-1至2024-12-31 截止日期：2024-12-31 编制人：黄振通2025-1-21 复核人：王裕昆2025-2-10
B4: 一、测试目的 | C4: 确定管理费用本期截止性是否正确；是否存在大额跨期项目。
B6: 二、测试步骤 | C6: 选取截止日前后大额凭证进行的截止性测试（如果公司截止日前几笔和后几笔发生的业务金额很小，如：只有几百元，则选择截止日前几天或后几天发生额较大的业务，测试其是否存在跨期情况）。
B8: 三、测试结果
B10: 所属单位 | C10: 日期 | D10: 凭证号 | E10: 内容 | F10: 对应科目 | G10: 金额 | H10: 是否跨期
H11: 是（√）否（×）
B22: 截止日前
B23: ---------------------------------------------------------------
B24: 截止日期：2023 年 12 月31日
B25: --------------------------------------------------------------------
B26: 截止日后

Sheet 4110-7
A1: << | B1: 管理费用凭证抽查表 | M1: 索引号： | N1: =目录!E11 -> 4110-7
B2: =目录!G3&目录!J3&" "&目录!G4&目录!H4&" "&目录!G5&目录!H5&" "&目录!I4&目录!J4&""&目录!L4&" "&目录!I5&目录!J5&""&目录!L5 -> 被审计单位：钢力金属 会计期间：2024-1-1至2024-12-31 截止日期：2024-12-31 编制人：黄振通2025-1-21 复核人：王裕昆2025-2-10
B4: 所属单位 | C4: 记账日期 | D4: 凭证编号 | E4: 业务内容 | F4: 会计科目 | G4: 借方金额 | H4: 贷方金额 | I4: 核对内容 （用“√”、“×”表示） | N4: 附件
I5: 1 | J5: 2 | K5: 3 | L5: 4 | M5: 5
B6: 钢力金属 | C6: 2024-05-27 | D6: 2024-05记-0007 | E6: 支付离休老干马永嘉同志花圈费租车费及慰问金 | F6: 管理费用\其他专项费用 | G6: 2000 | I6: √ | J6: √ | K6: √ | L6: √
B7: 钢力金属 | C7: 2024-10-08 | D7: 2024-10记-0004 | E7: 支付珠岛档案室2024年8月电费 | F7: 管理费用\水、电费\电费 | G7: 1827.36 | I7: √ | J7: √ | K7: √ | L7: √
B8: 钢力金属 | C8: 2024-12-23 | D8: 2024-12记-0002 | E8: 计提本月固定资产折旧 | F8: 管理费用\折旧费 | G8: 138932.13 | I8: √ | J8: √ | K8: √ | L8: √
B9: 钢力金属 | C9: 2024-12-24 | D9: 2024-12记-0003 | E9: 支付钢力总厂2024年财产险保险年费 | F9: 管理费用\其他管理费用 | G9: 6270.42 | I9: √ | J9: √ | K9: √ | L9: √
B10: 钢力金属 | C10: 2024-12-27 | D10: 2024-12记-0011 | E10: 计提2023年度无形资产摊销 | F10: 管理费用\无形资产摊销 | G10: 200821.29 | I10: √ | J10: √ | K10: √ | L10: √
B13: 核对内容说明： | C13: 1、原始凭证是否齐全；2、记账凭证与原始凭证是否相符；3、账务处理是否正确；
C14: 4、是否记录于恰当的会计期间；5、………………………………………………………………
B15: 审计说明：
B16: 1、经抽查凭证，原始凭证齐全、与记账凭证相符、账务处理正确、记录于恰当的会计期间。

Sheet TB
A1: 报表项目
A2: 一级科目 | B2: 二级科目 | C2: 三级科目
A3: 库存现金 | B3: 存货——原材料 | C3: 应付福利费——#职工奖励及福利基金
A4: 银行存款 | B4: 存货——库存商品（产成品）
A5: 其他货币资金 | B5: 其他非流动资产——特准储备物资
A6: 结算备付金 | B6: 应付职工薪酬——应付工资
A7: 拆出资金 | B7: 应付职工薪酬——应付福利费
A8: 交易性金融资产 | B8: 应交税费——应交税金
A9: 衍生金融资产 | B9: 应付债券——优先股
A10: 应收票据 | B10: 应付债券——永续债
A11: 应收票据坏账准备 | B11: 其他非流动负债——特准储备基金
A12: 应收账款 | B12: 其他权益工具——优先股
A13: 应收账款坏账准备 | B13: 其他权益工具——永续债
A14: 应收款项融资 | B14: 其他综合收益——外币报表折算差额
A15: 应收款项融资坏账准备 | B15: 财务费用——利息费用
... A20: 应收分保合同准备金 | B20: 营业外收入——政府补助
A21: 应收资金集中管理款
A22: 应收利息
A23: 应收利息坏账准备
A24: 应收股利
A25: 应收股利坏账准备
A26: 其他应收款
A27: 其他应收款坏账准备
A28: 买入返售金融资产
A29: 存货
A30: 存货跌价准备
A31: 合同资产
A32: 合同资产减值准备
... A170: 少数股东损益

Sheet ZZX-Template
B1: XX | J1: 索引号: | K1: XXXX-x
B2: xxx
B4: 序号 | C4: 项目
B5: 1
B6: 2
B7: 3
B8: 4
B9: 5
B11: 审计说明：
